<?xml version="1.0"?>

<!--

ROS urdf definition of TEO humanoid robot using xacro

RoboticsLab, University Carlos III of Madrid

Joint names and properties are according to REP-120:
Coordinate Frames for Humanoids Robots

http://ros.org/reps/rep-0120.html

TODO: I don't have info about waist_yaw and waist_pitch lower and upper angles
TODO: Some nodes need to publish /map, /odom, /base_footprint, etc.
TODO: No r_gripper l_gripper yet (just commented)

-->

<robot xmlns:xacro="http://ros.org/wiki/xacro">


<!-- *** TEO PARAMETERS -->

<!-- TEO minimum angles -->
<xacro:property name="hip_yaw_lower" value="-0.5235987875598299" />
<xacro:property name="hip_roll_lower" value="-2.094395102393195" />
<xacro:property name="hip_pitch_lower" value="-0.698131700797732" />
<xacro:property name="knee_pitch_lower" value="0.0" />
<xacro:property name="ankle_pitch_lower" value="-1.483529864195180" />
<xacro:property name="ankle_roll_lower" value="-0.349065850398866" />
<xacro:property name="waist_yaw_lower" value="-1.570796326794897" />
<xacro:property name="waist_pitch_lower" value="0.0" />
<xacro:property name="shoulder_pitch_lower" value="-3.141592653589793" />
<xacro:property name="shoulder_roll_lower" value="-0.785398163397448" />
<xacro:property name="shoulder_yaw_lower" value="-1.047197551196598" />
<xacro:property name="elbow_pitch_lower" value="-1.745329251994330" />
<xacro:property name="wrist_yaw_lower" value="-0.698131700797732" />
<xacro:property name="wrist_pitch_lower" value="-1.832595714594046" />

<!-- TEO maximum angles -->
<xacro:property name="hip_yaw_upper" value="0.418879020478639" />
<xacro:property name="hip_roll_upper" value="0.785398163397448" />
<xacro:property name="hip_pitch_upper" value="0.523598775598299" />
<xacro:property name="knee_pitch_upper" value="1.570796326794897" />
<xacro:property name="ankle_pitch_upper" value="1.483529864195180" />
<xacro:property name="ankle_roll_upper" value="0.349065850398866" />
<xacro:property name="waist_yaw_upper" value="1.570796326794897" />
<xacro:property name="waist_pitch_upper" value="0.785398163397448" />
<xacro:property name="shoulder_pitch_upper" value="3.141592653589793" />
<xacro:property name="shoulder_roll_upper" value="2.094395102393195" />
<xacro:property name="shoulder_yaw_upper" value="1.047197551196598" />
<xacro:property name="elbow_pitch_upper" value="1.745329251994330" />
<xacro:property name="wrist_yaw_upper" value="0.959931088596881" />
<xacro:property name="wrist_pitch_upper" value="1.832595714594046" />

<!-- TEO effort limit of the angles -->
<xacro:property name="hip_yaw_effort" value="30.0" />
<xacro:property name="hip_roll_effort" value="30.0" />
<xacro:property name="hip_pitch_effort" value="30.0" />
<xacro:property name="knee_pitch_effort" value="30.0" />
<xacro:property name="ankle_pitch_effort" value="30.0" />
<xacro:property name="ankle_roll_effort" value="30.0" />
<xacro:property name="waist_yaw_effort" value="30.0" />
<xacro:property name="waist_pitch_effort" value="30.0" />
<xacro:property name="shoulder_pitch_effort" value="30.0" />
<xacro:property name="shoulder_roll_effort" value="30.0" />
<xacro:property name="shoulder_yaw_effort" value="30.0" />
<xacro:property name="elbow_pitch_effort" value="30.0" />
<xacro:property name="wrist_yaw_effort" value="30.0" />
<xacro:property name="wrist_pitch_effort" value="30.0" />

<!-- TEO velocity limit of the angles-->
<xacro:property name="hip_yaw_velocity" value="3.0" />
<xacro:property name="hip_roll_velocity" value="3.0" />
<xacro:property name="hip_pitch_velocity" value="3.0" />
<xacro:property name="knee_pitch_velocity" value="3.0" />
<xacro:property name="ankle_pitch_velocity" value="3.0" />
<xacro:property name="ankle_roll_velocity" value="3.0" />
<xacro:property name="waist_yaw_velocity" value="3.0" />
<xacro:property name="waist_pitch_velocity" value="3.0" />
<xacro:property name="shoulder_pitch_velocity" value="3.0" />
<xacro:property name="shoulder_roll_velocity" value="3.0" />
<xacro:property name="shoulder_yaw_velocity" value="3.0" />
<xacro:property name="elbow_pitch_velocity" value="3.0" />
<xacro:property name="wrist_yaw_velocity" value="3.0" />
<xacro:property name="wrist_pitch_velocity" value="3.0" />


<!-- TEO torso -->
<xacro:property name="waist_link1" value="0.0" />
<xacro:property name="waist_link2" value="0.287" />
<xacro:property name="torso_link1" value="0.0" />
<xacro:property name="torso_link2" value="0.06" />


<!-- TEO legs -->
<xacro:property name="leg_link1" value="0.146" />
<xacro:property name="leg_link2" value="0.33" />
<xacro:property name="leg_link3" value="0.3" />
<xacro:property name="leg_link4" value="0.033" />
<xacro:property name="leg_link5" value="0.124" />

<!-- TEO arms -->
<xacro:property name="chest_link1" value="0.0" />
<xacro:property name="chest_link2" value="0.245" />
<xacro:property name="arm_link1" value="0.340" />
<xacro:property name="arm_link2" value="0.337" />
<xacro:property name="arm_link3" value="0.210" />

  <!-- Useful parameters -->
  <xacro:property name="pi" value="3.1415926535897931"/>
  <xacro:property name="pi_2" value="1.5707963267948966"/>



<!--***************
**** LINKS ****
***************-->


<!-- **** Torso **** -->

  <!-- base_link is rigidly attached to the robot root body.
It is recommended to choose the robot waist as its root body -->
  <link name="base_link" />

  <link name="torso" >
    <!--<inertial>
<origin xyz="0 0 0" rpy="0 0 0"/>
<mass value="1.0"/>
<inertia ixx="0.001" ixy="0.001" ixzv"0" iyy="0.001" iyz="0.001" izz="0.001" />
</inertial> -->
    <xacro:insert_visualization_torso/>
    <xacro:insert_visualization_shoulder_pitch side="r" reflect="-1"/>
    <xacro:insert_visualization_shoulder_pitch side="l" reflect="1"/>
  </link>

  <link name="waist" >
    <!--<inertial>
<origin xyz="0 0 0" rpy="0 0 0"/>
<mass value="1.0"/>
<inertia ixx="0.001" ixy="0.001" ixzv"0" iyy="0.001" iyz="0.001" izz="0.001" />
</inertial> -->
    <xacro:insert_visualization_waist/>
    <xacro:insert_visualization_hip_yaw side="r" reflect="-1"/>
    <xacro:insert_visualization_hip_yaw side="l" reflect="1"/>
  </link>

  <link name="waist_yaw_link" >
    <!--<inertial>
<origin xyz="0 0 0" rpy="0 0 0"/>
<mass value="1.0"/>
<inertia ixx="0.001" ixy="0.001" ixzv"0" iyy="0.001" iyz="0.001" izz="0.001" />
</inertial> -->
    <xacro:insert_visualization_waist_yaw/>
  </link>

  <link name="waist_pitch_link" >
    <!--<inertial>
<origin xyz="0 0 0" rpy="0 0 0"/>
<mass value="1.0"/>
<inertia ixx="0.001" ixy="0.001" ixzv"0" iyy="0.001" iyz="0.001" izz="0.001" />
</inertial> -->
    <xacro:insert_visualization_waist_pitch/>
  </link>


<!-- **** Legs **** -->

  <xacro:macro name="legs_links" params="side reflect">
    <link name="${side}_hip_yaw_link">
      <!--inertial>
<origin xyz="0.0 ${reflect*0.0} 0.0" rpy="0 0 0"/>
<mass value="1.0"/>
<inertia ixx="0.001" ixy="0.001" ixzv"0" iyy="0.001" iyz="0.001" izz="0.001" />
</inertial-->
    </link>
    <link name="${side}_hip_roll_link">
      <!--inertial>
<origin xyz="0.0 ${reflect*0.0} 0.0" rpy="0 0 0"/>
<mass value="1.0"/>
<inertia ixx="0.001" ixy="0.001" ixzv"0" iyy="0.001" iyz="0.001" izz="0.001" />
</inertial-->
    </link>
    <link name="${side}_hip_pitch_link">
      <!--inertial>
<origin xyz="0.0 ${reflect*0.0} 0.0" rpy="0 0 0"/>
<mass value="1.0"/>
<inertia ixx="0.001" ixy="0.001" ixzv"0" iyy="0.001" iyz="0.001" izz="0.001" />
</inertial-->
      <xacro:insert_visualization_hip_pitch side="${side}" reflect="${reflect}"/>
    </link>
    <link name="${side}_knee_pitch_link">
      <!--inertial>
<origin xyz="0.0 ${reflect*0.0} 0.0" rpy="0 0 0"/>
<mass value="1.0"/>
<inertia ixx="0.001" ixy="0.001" ixzv"0" iyy="0.001" iyz="0.001" izz="0.001" />
</inertial-->
      <xacro:insert_visualization_knee_pitch side="${side}" reflect="${reflect}"/>
    </link>
    <link name="${side}_ankle_pitch_link">
      <!--inertial>
<origin xyz="0.0 ${reflect*0.0} 0.0" rpy="0 0 0"/>
<mass value="1.0"/>
<inertia ixx="0.001" ixy="0.001" ixzv"0" iyy="0.001" iyz="0.001" izz="0.001" />
</inertial-->
      <xacro:insert_visualization_ankle_pitch side="${side}" reflect="${reflect}"/>
    </link>
    <link name="${side}_ankle_roll_link">
      <!--inertial>
<origin xyz="0.0 ${reflect*0.0} 0.0" rpy="0 0 0"/>
<mass value="1.0"/>
<inertia ixx="0.001" ixy="0.001" ixzv"0" iyy="0.001" iyz="0.001" izz="0.001" />
</inertial-->
      <xacro:insert_visualization_ankle_roll side="${side}" reflect="${reflect}"/>
    </link>
    <link name="${side}_sole">
      <!--inertial>
<origin xyz="0.0 ${reflect*0.0} 0.0" rpy="0 0 0"/>
<mass value="1.0"/>
<inertia ixx="0.001" ixy="0.001" ixzv"0" iyy="0.001" iyz="0.001" izz="0.001" />
</inertial-->
      <xacro:insert_visualization_sole side="${side}" reflect="${reflect}"/>
    </link>

  </xacro:macro>

  <xacro:legs_links side="l" reflect="1"/>
  <xacro:legs_links side="r" reflect="-1"/>



<!-- **** Arms **** -->
  <xacro:macro name="arms_links" params="side reflect">
    <link name="${side}_shoulder_pitch_link">
      <!--inertial>
<origin xyz="0.0 ${reflect*0.0} 0.0" rpy="0 0 0"/>
<mass value="1.0"/>
<inertia ixx="0.001" ixy="0.001" ixzv"0" iyy="0.001" iyz="0.001" izz="0.001" />
</inertial-->
    </link>
    <link name="${side}_shoulder_roll_link">
      <!--inertial>
<origin xyz="0.0 ${reflect*0.0} 0.0" rpy="0 0 0"/>
<mass value="1.0"/>
<inertia ixx="0.001" ixy="0.001" ixzv"0" iyy="0.001" iyz="0.001" izz="0.001" />
</inertial-->
    </link>
    <link name="${side}_shoulder_yaw_link">
      <!--inertial>
<origin xyz="0.0 ${reflect*0.0} 0.0" rpy="0 0 0"/>
<mass value="1.0"/>
<inertia ixx="0.001" ixy="0.001" ixzv"0" iyy="0.001" iyz="0.001" izz="0.001" />
</inertial-->
      <xacro:insert_visualization_shoulder_yaw side="${side}" reflect="${reflect}"/>
    </link>
    <link name="${side}_elbow_pitch_link">
      <!--inertial>
<origin xyz="0.0 ${reflect*0.0} 0.0" rpy="0 0 0"/>
<mass value="1.0"/>
<inertia ixx="0.001" ixy="0.001" ixzv"0" iyy="0.001" iyz="0.001" izz="0.001" />
</inertial-->
      <xacro:insert_visualization_elbow_pitch side="${side}" reflect="${reflect}"/>
    </link>
    <link name="${side}_wrist_yaw_link">
      <!--inertial>
<origin xyz="0.0 ${reflect*0.0} 0.0" rpy="0 0 0"/>
<mass value="1.0"/>
<inertia ixx="0.001" ixy="0.001" ixzv"0" iyy="0.001" iyz="0.001" izz="0.001" />
</inertial-->
    </link>
    <link name="${side}_wrist_pitch_link">
      <!--inertial>
<origin xyz="0.0 ${reflect*0.0} 0.0" rpy="0 0 0"/>
<mass value="1.0"/>
<inertia ixx="0.001" ixy="0.001" ixzv"0" iyy="0.001" iyz="0.001" izz="0.001" />
</inertial-->
    </link>
  </xacro:macro>

  <xacro:arms_links side="l" reflect="1"/>
  <xacro:arms_links side="r" reflect="-1"/>


<!--***************
**** JOINTS ****
***************-->

<!-- **** Torso **** -->

  <joint name="waist_yaw" type="revolute">
    <parent link="waist"/>
    <child link="waist_yaw_link"/>
    <origin xyz="${waist_link1} 0 ${waist_link2}" rpy="0 0 0" />
    <axis xyz="0 0 1"/>
    <limit velocity="${waist_yaw_velocity}" effort="${waist_yaw_effort}" lower="${waist_yaw_lower}" upper="${waist_yaw_upper}"/>
  </joint>

  <joint name="waist_pitch" type="revolute">
    <parent link="waist_yaw_link"/>
    <child link="waist_pitch_link"/>
    <origin xyz="-${torso_link1} 0 0" rpy="0 0 0" />
    <axis xyz="0 1 0"/>
    <limit velocity="${waist_pitch_velocity}" effort="${waist_pitch_effort}" lower="${waist_pitch_lower}" upper="${waist_pitch_upper}"/>
  </joint>

  <joint name="torso_joint" type="fixed">
    <parent link="waist_pitch_link"/>
    <child link="torso"/>
    <origin xyz="0 0 ${torso_link2}" rpy="0 0 0" />
  </joint>


<!-- **** Legs **** -->

  <xacro:macro name="legs_joints" params="side reflect">
    <joint name="${side}_hip_yaw" type="revolute">
      <parent link="waist"/>
      <child link="${side}_hip_yaw_link"/>
      <origin xyz="0 ${reflect*leg_link1} 0" rpy="0 0 0"/> <!--y=Leg_link1-->
      <axis xyz="0 0 1"/>
      <limit velocity="${hip_yaw_velocity}" effort="${hip_yaw_effort}" lower="${hip_yaw_lower}" upper="${hip_yaw_upper}"/>
    </joint>

    <joint name="${side}_hip_roll" type="revolute">
      <parent link="${side}_hip_yaw_link"/>
      <child link="${side}_hip_roll_link"/>
      <origin xyz="0 0 0" rpy="0 0 0"/>
      <axis xyz="1 0 0"/>
      <limit velocity="${hip_roll_velocity}" effort="${hip_roll_effort}" lower="${hip_roll_lower}" upper="${hip_roll_upper}"/>
    </joint>

    <joint name="${side}_hip_pitch" type="revolute">
      <parent link="${side}_hip_roll_link"/>
      <child link="${side}_hip_pitch_link"/>
      <origin xyz="0 0 0" rpy="0 0 0"/>
      <axis xyz="0 1 0"/>
      <limit velocity="${hip_pitch_velocity}" effort="${hip_pitch_effort}" lower="${hip_pitch_lower}" upper="${hip_pitch_upper}"/>
    </joint>

    <joint name="${side}_knee_pitch" type="revolute">
      <parent link="${side}_hip_pitch_link"/>
      <child link="${side}_knee_pitch_link"/>
      <origin xyz="0 0 -${leg_link2}" rpy="0 0 0"/>
      <axis xyz="0 1 0"/>
      <limit velocity="${knee_pitch_velocity}" effort="${knee_pitch_effort}" lower="${knee_pitch_lower}" upper="${knee_pitch_upper}"/>
    </joint>

    <joint name="${side}_ankle_pitch" type="revolute">
      <parent link="${side}_knee_pitch_link"/>
      <child link="${side}_ankle_pitch_link"/>
      <origin xyz="0 ${reflect*-leg_link4} -${leg_link3}" rpy="0 0 0"/>
      <axis xyz="0 1 0"/>
      <limit velocity="${ankle_pitch_velocity}" effort="${ankle_pitch_effort}" lower="${ankle_pitch_lower}" upper="${ankle_pitch_upper}"/>
    </joint>

    <joint name="${side}_ankle_roll" type="revolute">
      <parent link="${side}_ankle_pitch_link"/>
      <child link="${side}_ankle_roll_link"/>
      <origin xyz="0 0 0" rpy="0 0 0"/>
      <axis xyz="1 0 0"/>
      <limit velocity="${ankle_roll_velocity}" effort="${ankle_roll_effort}" lower="${ankle_roll_lower}" upper="${ankle_roll_upper}"/>
    </joint>

    <joint name="${side}_sole_joint" type="fixed">
      <parent link="${side}_ankle_roll_link"/>
      <child link="${side}_sole"/>
      <origin xyz="0 0 -${leg_link5}" rpy="0 0 0"/>
    </joint>

  </xacro:macro>

  <xacro:legs_joints side="l" reflect="1"/>
  <xacro:legs_joints side="r" reflect="-1"/>

<!-- **** Arms **** -->
  <xacro:macro name="arms_joints" params="side reflect">
    <joint name="${side}_shoulder_pitch" type="revolute">
      <parent link="torso"/>
      <child link="${side}_shoulder_pitch_link"/>
      <origin xyz="-${chest_link1} ${reflect*arm_link1} ${chest_link2}" rpy="0 0 0"/>
      <axis xyz="0 1 0"/>
      <limit velocity="${shoulder_pitch_velocity}" effort="${shoulder_pitch_effort}" lower="${shoulder_pitch_lower}" upper="${shoulder_pitch_upper}"/>
    </joint>
    <joint name="${side}_shoulder_roll" type="revolute">
      <parent link="${side}_shoulder_pitch_link"/>
      <child link="${side}_shoulder_roll_link"/>
      <origin xyz="0 0 0" rpy="0 0 0"/>
      <axis xyz="1 0 0"/>
      <limit velocity="${shoulder_roll_velocity}" effort="${shoulder_roll_effort}" lower="${shoulder_roll_lower}" upper="${shoulder_roll_upper}"/>
    </joint>
    <joint name="${side}_shoulder_yaw" type="revolute">
      <parent link="${side}_shoulder_roll_link"/>
      <child link="${side}_shoulder_yaw_link"/>
      <origin xyz="0 0 0" rpy="0 0 0"/>
      <axis xyz="0 0 1"/>
      <limit velocity="${shoulder_yaw_velocity}" effort="${shoulder_yaw_effort}" lower="${shoulder_yaw_lower}" upper="${shoulder_yaw_upper}"/>
    </joint>
    <joint name="${side}_elbow_pitch" type="revolute">
      <parent link="${side}_shoulder_yaw_link"/>
      <child link="${side}_elbow_pitch_link"/>
      <origin xyz="0 0 -${arm_link2}" rpy="0 0 0"/>
      <axis xyz="0 1 0"/>
      <limit velocity="${elbow_pitch_velocity}" effort="${elbow_pitch_effort}" lower="${elbow_pitch_lower}" upper="${elbow_pitch_upper}"/>
    </joint>
    <joint name="${side}_wrist_yaw" type="revolute">
      <parent link="${side}_elbow_pitch_link"/>
      <child link="${side}_wrist_yaw_link"/>
      <origin xyz="0 0 -${arm_link3}" rpy="0 0 0"/>
      <axis xyz="0 0 1"/>
      <limit velocity="${wrist_yaw_velocity}" effort="${wrist_yaw_effort}" lower="${wrist_yaw_lower}" upper="${wrist_yaw_upper}"/>
    </joint>
    <joint name="${side}_wrist_pitch" type="revolute">
      <parent link="${side}_wrist_yaw_link"/>
      <child link="${side}_wrist_pitch_link"/>
      <origin xyz="0 0 0" rpy="0 0 0"/>
      <axis xyz="0 1 0"/>
      <limit velocity="${wrist_pitch_velocity}" effort="${wrist_pitch_effort}" lower="${wrist_pitch_lower}" upper="${wrist_pitch_upper}"/>
    </joint>
  </xacro:macro>

  <xacro:arms_joints side="l" reflect="1"/>
  <xacro:arms_joints side="r" reflect="-1"/>

<!-- **** Fictitious joints **** -->

  <joint name="base_joint" type="fixed">
    <child link="waist"/>
    <parent link="base_link"/>
    <origin xyz="0 0 0" rpy="0 0 0" />
  </joint>

</robot>
