<?xml version="1.0" ?>
<!-- =================================================================================== -->
<!-- |    This document was autogenerated by xacro from teo_humanoid_complete_vis.urdf.xacro | -->
<!-- |    EDITING THIS FILE BY HAND IS NOT RECOMMENDED                                 | -->
<!-- =================================================================================== -->
<robot name="teo" xmlns:xacro="http://ros.org/wiki/xacro">
  <!--
  ROS urdf definition of TEO humanoid robot
  
  Author: Domingo Esteban
  RoboticsLab, University Carlos III de Madrid
  
  This file loads TEO model with a basic visualization.

  If you want to convert this xacro file into an urdf file:
  $ rosrun xacro xacro.py teo_humanoid.urdf.xacro > teo_humanoid.urdf
-->
  <link name="base_link"/>
  <link name="torso">
    <!--<inertial>
      <origin xyz="0 0 0" rpy="0 0 0"/>
      <mass value="1.0"/>
      <inertia ixx="0.001"  ixy="0.001"  ixzv"0" iyy="0.001" iyz="0.001" izz="0.001" />
    </inertial> -->
    <visual>
      <!-- one box -->
      <!--origin xyz="0 0 0.1" rpy="0 0 0"/-->
      <origin rpy="0 0 0" xyz="0 0 0.03"/>
      <geometry>
        <!--box size="0.1 0.45 0.292"/-->
        <mesh filename="package://teo_description/meshes/torso/chest_reduced2.dae"/>
      </geometry>
      <material name="LightGrey"/>
    </visual>
  </link>
  <link name="waist">
    <!--<inertial>
      <origin xyz="0 0 0" rpy="0 0 0"/>
      <mass value="1.0"/>
      <inertia ixx="0.001"  ixy="0.001"  ixzv"0" iyy="0.001" iyz="0.001" izz="0.001" />
    </inertial> -->
    <visual>
      <geometry>
        <mesh filename="package://teo_description/meshes/legs/r_axialhip.dae"/>
      </geometry>
      <material name="grey"/>
      <origin rpy="0 0 0" xyz="0 -0.146 0"/>
    </visual>
    <visual>
      <geometry>
        <mesh filename="package://teo_description/meshes/legs/l_axialhip.dae"/>
      </geometry>
      <material name="grey"/>
      <origin rpy="0 0 0" xyz="0 0.146 0"/>
    </visual>
  </link>
  <link name="waist_yaw_link">
    <!--<inertial>
      <origin xyz="0 0 0" rpy="0 0 0"/>
      <mass value="1.0"/>
      <inertia ixx="0.001"  ixy="0.001"  ixzv"0" iyy="0.001" iyz="0.001" izz="0.001" />
    </inertial> -->
    <visual>
      <origin rpy="0 0 0" xyz="0 0 0.025"/>
      <geometry>
        <!--sphere radius="1.0"/-->
        <cylinder length="0.06" radius="0.02"/>
      </geometry>
      <material name="LightGrey"/>
    </visual>
  </link>
  <link name="waist_pitch_link">
    <!--<inertial>
      <origin xyz="0 0 0" rpy="0 0 0"/>
      <mass value="1.0"/>
      <inertia ixx="0.001"  ixy="0.001"  ixzv"0" iyy="0.001" iyz="0.001" izz="0.001" />
    </inertial> -->
    <visual>
      <origin rpy="1.57079632679 0 0" xyz="0 0 0"/>
      <geometry>
        <!--sphere radius="1.0"/-->
        <cylinder length="0.06" radius="0.02"/>
      </geometry>
      <material name="LightGrey"/>
    </visual>
  </link>
  <link name="l_hip_yaw_link">
    <!--inertial>
        <origin xyz="0.0 ${reflect*0.0} 0.0" rpy="0 0 0"/>
        <mass value="1.0"/>
        <inertia ixx="0.001"  ixy="0.001"  ixzv"0" iyy="0.001" iyz="0.001" izz="0.001" />
      </inertial-->
  </link>
  <link name="l_hip_roll_link">
    <!--inertial>
        <origin xyz="0.0 ${reflect*0.0} 0.0" rpy="0 0 0"/>
        <mass value="1.0"/>
        <inertia ixx="0.001"  ixy="0.001"  ixzv"0" iyy="0.001" iyz="0.001" izz="0.001" />
      </inertial-->
    <visual>
      <geometry>
        <mesh filename="package://teo_description/meshes/legs/l_hip.dae"/>
      </geometry>
      <material name="grey"/>
      <origin rpy="0 0 0" xyz="0 0 0"/>
    </visual>
  </link>
  <link name="l_hip_pitch_link">
    <!--inertial>
        <origin xyz="0.0 ${reflect*0.0} 0.0" rpy="0 0 0"/>
        <mass value="1.0"/>
        <inertia ixx="0.001"  ixy="0.001"  ixzv"0" iyy="0.001" iyz="0.001" izz="0.001" />
      </inertial-->
    <visual>
      <geometry>
        <mesh filename="package://teo_description/meshes/legs/l_thigh.dae"/>
      </geometry>
      <material name="grey"/>
      <origin rpy="0 0 0" xyz="0.013 0 -0.33"/>
    </visual>
  </link>
  <link name="l_knee_pitch_link">
    <!--inertial>
        <origin xyz="0.0 ${reflect*0.0} 0.0" rpy="0 0 0"/>
        <mass value="1.0"/>
        <inertia ixx="0.001"  ixy="0.001"  ixzv"0" iyy="0.001" iyz="0.001" izz="0.001" />
      </inertial-->
    <visual>
      <geometry>
        <mesh filename="package://teo_description/meshes/legs/l_tibia.dae"/>
      </geometry>
      <material name="grey"/>
      <origin rpy="0 0 0" xyz="-0.013 -0.033 -0.3"/>
    </visual>
  </link>
  <link name="l_ankle_pitch_link">
    <!--inertial>
        <origin xyz="0.0 ${reflect*0.0} 0.0" rpy="0 0 0"/>
        <mass value="1.0"/>
        <inertia ixx="0.001"  ixy="0.001"  ixzv"0" iyy="0.001" iyz="0.001" izz="0.001" />
      </inertial-->
    <visual>
      <geometry>
        <mesh filename="package://teo_description/meshes/legs/l_ankle.dae"/>
      </geometry>
      <material name="grey"/>
      <origin rpy="0 0 0" xyz="0 0 0"/>
    </visual>
  </link>
  <link name="l_ankle_roll_link">
    <!--inertial>
        <origin xyz="0.0 ${reflect*0.0} 0.0" rpy="0 0 0"/>
        <mass value="1.0"/>
        <inertia ixx="0.001"  ixy="0.001"  ixzv"0" iyy="0.001" iyz="0.001" izz="0.001" />
      </inertial-->
    <visual>
      <geometry>
        <mesh filename="package://teo_description/meshes/legs/l_foot.dae"/>
      </geometry>
      <material name="grey"/>
      <origin rpy="0 0 0" xyz="0 0 0"/>
    </visual>
  </link>
  <link name="l_sole">
    <!--inertial>
        <origin xyz="0.0 ${reflect*0.0} 0.0" rpy="0 0 0"/>
        <mass value="1.0"/>
        <inertia ixx="0.001"  ixy="0.001"  ixzv"0" iyy="0.001" iyz="0.001" izz="0.001" />
      </inertial-->
  </link>
  <link name="r_hip_yaw_link">
    <!--inertial>
        <origin xyz="0.0 ${reflect*0.0} 0.0" rpy="0 0 0"/>
        <mass value="1.0"/>
        <inertia ixx="0.001"  ixy="0.001"  ixzv"0" iyy="0.001" iyz="0.001" izz="0.001" />
      </inertial-->
  </link>
  <link name="r_hip_roll_link">
    <!--inertial>
        <origin xyz="0.0 ${reflect*0.0} 0.0" rpy="0 0 0"/>
        <mass value="1.0"/>
        <inertia ixx="0.001"  ixy="0.001"  ixzv"0" iyy="0.001" iyz="0.001" izz="0.001" />
      </inertial-->
    <visual>
      <geometry>
        <mesh filename="package://teo_description/meshes/legs/r_hip.dae"/>
      </geometry>
      <material name="grey"/>
      <origin rpy="0 0 0" xyz="0 0 0"/>
    </visual>
  </link>
  <link name="r_hip_pitch_link">
    <!--inertial>
        <origin xyz="0.0 ${reflect*0.0} 0.0" rpy="0 0 0"/>
        <mass value="1.0"/>
        <inertia ixx="0.001"  ixy="0.001"  ixzv"0" iyy="0.001" iyz="0.001" izz="0.001" />
      </inertial-->
    <visual>
      <geometry>
        <mesh filename="package://teo_description/meshes/legs/r_thigh.dae"/>
      </geometry>
      <material name="grey"/>
      <origin rpy="0 0 0" xyz="0.013 0 -0.33"/>
    </visual>
  </link>
  <link name="r_knee_pitch_link">
    <!--inertial>
        <origin xyz="0.0 ${reflect*0.0} 0.0" rpy="0 0 0"/>
        <mass value="1.0"/>
        <inertia ixx="0.001"  ixy="0.001"  ixzv"0" iyy="0.001" iyz="0.001" izz="0.001" />
      </inertial-->
    <visual>
      <geometry>
        <mesh filename="package://teo_description/meshes/legs/r_tibia.dae"/>
      </geometry>
      <material name="grey"/>
      <origin rpy="0 0 0" xyz="-0.013 0.033 -0.3"/>
    </visual>
  </link>
  <link name="r_ankle_pitch_link">
    <!--inertial>
        <origin xyz="0.0 ${reflect*0.0} 0.0" rpy="0 0 0"/>
        <mass value="1.0"/>
        <inertia ixx="0.001"  ixy="0.001"  ixzv"0" iyy="0.001" iyz="0.001" izz="0.001" />
      </inertial-->
    <visual>
      <geometry>
        <mesh filename="package://teo_description/meshes/legs/r_ankle.dae"/>
      </geometry>
      <material name="grey"/>
      <origin rpy="0 0 0" xyz="0 0 0"/>
    </visual>
  </link>
  <link name="r_ankle_roll_link">
    <!--inertial>
        <origin xyz="0.0 ${reflect*0.0} 0.0" rpy="0 0 0"/>
        <mass value="1.0"/>
        <inertia ixx="0.001"  ixy="0.001"  ixzv"0" iyy="0.001" iyz="0.001" izz="0.001" />
      </inertial-->
    <visual>
      <geometry>
        <mesh filename="package://teo_description/meshes/legs/r_foot.dae"/>
      </geometry>
      <material name="grey"/>
      <origin rpy="0 0 0" xyz="0 0 0"/>
    </visual>
  </link>
  <link name="r_sole">
    <!--inertial>
        <origin xyz="0.0 ${reflect*0.0} 0.0" rpy="0 0 0"/>
        <mass value="1.0"/>
        <inertia ixx="0.001"  ixy="0.001"  ixzv"0" iyy="0.001" iyz="0.001" izz="0.001" />
      </inertial-->
  </link>
  <link name="l_shoulder_pitch_link">
    <!--inertial>
        <origin xyz="0.0 ${reflect*0.0} 0.0" rpy="0 0 0"/>
        <mass value="1.0"/>
        <inertia ixx="0.001"  ixy="0.001"  ixzv"0" iyy="0.001" iyz="0.001" izz="0.001" />
      </inertial-->
  </link>
  <link name="l_shoulder_roll_link">
    <!--inertial>
        <origin xyz="0.0 ${reflect*0.0} 0.0" rpy="0 0 0"/>
        <mass value="1.0"/>
        <inertia ixx="0.001"  ixy="0.001"  ixzv"0" iyy="0.001" iyz="0.001" izz="0.001" />
      </inertial-->
  </link>
  <link name="l_shoulder_yaw_link">
    <!--inertial>
        <origin xyz="0.0 ${reflect*0.0} 0.0" rpy="0 0 0"/>
        <mass value="1.0"/>
        <inertia ixx="0.001"  ixy="0.001"  ixzv"0" iyy="0.001" iyz="0.001" izz="0.001" />
      </inertial-->
    <visual>
      <geometry>
        <!--box size="0.08 0.08 ${arm_link2}"/-->
        <!--mesh filename="package://teo_description/meshes/legs/${side}_foot.dae"/-->
        <mesh filename="package://teo_description/meshes/arms/l_arm.dae"/>
      </geometry>
      <material name="grey"/>
      <!--origin rpy="0 0 0" xyz="0 0 -${arm_link2/2}"/-->
      <origin rpy="0 0 0" xyz="0 0 -0.1235"/>
    </visual>
  </link>
  <link name="l_elbow_pitch_link">
    <!--inertial>
        <origin xyz="0.0 ${reflect*0.0} 0.0" rpy="0 0 0"/>
        <mass value="1.0"/>
        <inertia ixx="0.001"  ixy="0.001"  ixzv"0" iyy="0.001" iyz="0.001" izz="0.001" />
      </inertial-->
    <visual>
      <geometry>
        <!--box size="0.06 0.06 ${arm_link3}"/-->
        <mesh filename="package://teo_description/meshes/arms/l_forearm.dae"/>
      </geometry>
      <material name="grey"/>
      <origin rpy="0 0 0" xyz="0 0 -0.105"/>
    </visual>
  </link>
  <link name="l_wrist_yaw_link">
    <!--inertial>
        <origin xyz="0.0 ${reflect*0.0} 0.0" rpy="0 0 0"/>
        <mass value="1.0"/>
        <inertia ixx="0.001"  ixy="0.001"  ixzv"0" iyy="0.001" iyz="0.001" izz="0.001" />
      </inertial-->
  </link>
  <link name="l_wrist_pitch_link">
    <!--inertial>
        <origin xyz="0.0 ${reflect*0.0} 0.0" rpy="0 0 0"/>
        <mass value="1.0"/>
        <inertia ixx="0.001"  ixy="0.001"  ixzv"0" iyy="0.001" iyz="0.001" izz="0.001" />
      </inertial-->
  </link>
  <link name="r_shoulder_pitch_link">
    <!--inertial>
        <origin xyz="0.0 ${reflect*0.0} 0.0" rpy="0 0 0"/>
        <mass value="1.0"/>
        <inertia ixx="0.001"  ixy="0.001"  ixzv"0" iyy="0.001" iyz="0.001" izz="0.001" />
      </inertial-->
  </link>
  <link name="r_shoulder_roll_link">
    <!--inertial>
        <origin xyz="0.0 ${reflect*0.0} 0.0" rpy="0 0 0"/>
        <mass value="1.0"/>
        <inertia ixx="0.001"  ixy="0.001"  ixzv"0" iyy="0.001" iyz="0.001" izz="0.001" />
      </inertial-->
  </link>
  <link name="r_shoulder_yaw_link">
    <!--inertial>
        <origin xyz="0.0 ${reflect*0.0} 0.0" rpy="0 0 0"/>
        <mass value="1.0"/>
        <inertia ixx="0.001"  ixy="0.001"  ixzv"0" iyy="0.001" iyz="0.001" izz="0.001" />
      </inertial-->
    <visual>
      <geometry>
        <!--box size="0.08 0.08 ${arm_link2}"/-->
        <!--mesh filename="package://teo_description/meshes/legs/${side}_foot.dae"/-->
        <mesh filename="package://teo_description/meshes/arms/r_arm.dae"/>
      </geometry>
      <material name="grey"/>
      <!--origin rpy="0 0 0" xyz="0 0 -${arm_link2/2}"/-->
      <origin rpy="0 0 0" xyz="0 0 -0.1235"/>
    </visual>
  </link>
  <link name="r_elbow_pitch_link">
    <!--inertial>
        <origin xyz="0.0 ${reflect*0.0} 0.0" rpy="0 0 0"/>
        <mass value="1.0"/>
        <inertia ixx="0.001"  ixy="0.001"  ixzv"0" iyy="0.001" iyz="0.001" izz="0.001" />
      </inertial-->
    <visual>
      <geometry>
        <!--box size="0.06 0.06 ${arm_link3}"/-->
        <mesh filename="package://teo_description/meshes/arms/r_forearm.dae"/>
      </geometry>
      <material name="grey"/>
      <origin rpy="0 0 0" xyz="0 0 -0.105"/>
    </visual>
  </link>
  <link name="r_wrist_yaw_link">
    <!--inertial>
        <origin xyz="0.0 ${reflect*0.0} 0.0" rpy="0 0 0"/>
        <mass value="1.0"/>
        <inertia ixx="0.001"  ixy="0.001"  ixzv"0" iyy="0.001" iyz="0.001" izz="0.001" />
      </inertial-->
  </link>
  <link name="r_wrist_pitch_link">
    <!--inertial>
        <origin xyz="0.0 ${reflect*0.0} 0.0" rpy="0 0 0"/>
        <mass value="1.0"/>
        <inertia ixx="0.001"  ixy="0.001"  ixzv"0" iyy="0.001" iyz="0.001" izz="0.001" />
      </inertial-->
  </link>
  <joint name="waist_yaw" type="revolute">
    <parent link="waist"/>
    <child link="waist_yaw_link"/>
    <origin rpy="0 0 0" xyz="0.0 0 0.287"/>
    <axis xyz="0 0 1"/>
    <limit effort="30.0" lower="-1.57079632679" upper="1.57079632679" velocity="3.0"/>
  </joint>
  <joint name="waist_pitch" type="revolute">
    <parent link="waist_yaw_link"/>
    <child link="waist_pitch_link"/>
    <origin rpy="0 0 0" xyz="-0.0 0 0"/>
    <axis xyz="0 1 0"/>
    <limit effort="30.0" lower="0.0" upper="0.785398163397" velocity="3.0"/>
  </joint>
  <joint name="torso_joint" type="fixed">
    <parent link="waist_pitch_link"/>
    <child link="torso"/>
    <origin rpy="0 0 0" xyz="0 0 0.06"/>
  </joint>
  <joint name="l_hip_yaw" type="revolute">
    <parent link="waist"/>
    <child link="l_hip_yaw_link"/>
    <origin rpy="0 0 0" xyz="0 0.146 0"/>
    <!--y=Leg_link1-->
    <axis xyz="0 0 1"/>
    <limit effort="30.0" lower="-0.52359878756" upper="0.418879020479" velocity="3.0"/>
  </joint>
  <joint name="l_hip_roll" type="revolute">
    <parent link="l_hip_yaw_link"/>
    <child link="l_hip_roll_link"/>
    <origin rpy="0 0 0" xyz="0 0 0"/>
    <axis xyz="1 0 0"/>
    <limit effort="30.0" lower="-2.09439510239" upper="0.785398163397" velocity="3.0"/>
  </joint>
  <joint name="l_hip_pitch" type="revolute">
    <parent link="l_hip_roll_link"/>
    <child link="l_hip_pitch_link"/>
    <origin rpy="0 0 0" xyz="0 0 0"/>
    <axis xyz="0 1 0"/>
    <limit effort="30.0" lower="-0.698131700798" upper="0.523598775598" velocity="3.0"/>
  </joint>
  <joint name="l_knee_pitch" type="revolute">
    <parent link="l_hip_pitch_link"/>
    <child link="l_knee_pitch_link"/>
    <origin rpy="0 0 0" xyz="0 0 -0.33"/>
    <axis xyz="0 1 0"/>
    <limit effort="30.0" lower="0.0" upper="1.57079632679" velocity="3.0"/>
  </joint>
  <joint name="l_ankle_pitch" type="revolute">
    <parent link="l_knee_pitch_link"/>
    <child link="l_ankle_pitch_link"/>
    <origin rpy="0 0 0" xyz="0 -0.033 -0.3"/>
    <axis xyz="0 1 0"/>
    <limit effort="30.0" lower="-1.4835298642" upper="1.4835298642" velocity="3.0"/>
  </joint>
  <joint name="l_ankle_roll" type="revolute">
    <parent link="l_ankle_pitch_link"/>
    <child link="l_ankle_roll_link"/>
    <origin rpy="0 0 0" xyz="0 0 0"/>
    <axis xyz="1 0 0"/>
    <limit effort="30.0" lower="-0.349065850399" upper="0.349065850399" velocity="3.0"/>
  </joint>
  <joint name="l_sole_joint" type="fixed">
    <parent link="l_ankle_roll_link"/>
    <child link="l_sole"/>
    <origin rpy="0 0 0" xyz="0 0 -0.124"/>
  </joint>
  <joint name="r_hip_yaw" type="revolute">
    <parent link="waist"/>
    <child link="r_hip_yaw_link"/>
    <origin rpy="0 0 0" xyz="0 -0.146 0"/>
    <!--y=Leg_link1-->
    <axis xyz="0 0 1"/>
    <limit effort="30.0" lower="-0.52359878756" upper="0.418879020479" velocity="3.0"/>
  </joint>
  <joint name="r_hip_roll" type="revolute">
    <parent link="r_hip_yaw_link"/>
    <child link="r_hip_roll_link"/>
    <origin rpy="0 0 0" xyz="0 0 0"/>
    <axis xyz="1 0 0"/>
    <limit effort="30.0" lower="-2.09439510239" upper="0.785398163397" velocity="3.0"/>
  </joint>
  <joint name="r_hip_pitch" type="revolute">
    <parent link="r_hip_roll_link"/>
    <child link="r_hip_pitch_link"/>
    <origin rpy="0 0 0" xyz="0 0 0"/>
    <axis xyz="0 1 0"/>
    <limit effort="30.0" lower="-0.698131700798" upper="0.523598775598" velocity="3.0"/>
  </joint>
  <joint name="r_knee_pitch" type="revolute">
    <parent link="r_hip_pitch_link"/>
    <child link="r_knee_pitch_link"/>
    <origin rpy="0 0 0" xyz="0 0 -0.33"/>
    <axis xyz="0 1 0"/>
    <limit effort="30.0" lower="0.0" upper="1.57079632679" velocity="3.0"/>
  </joint>
  <joint name="r_ankle_pitch" type="revolute">
    <parent link="r_knee_pitch_link"/>
    <child link="r_ankle_pitch_link"/>
    <origin rpy="0 0 0" xyz="0 0.033 -0.3"/>
    <axis xyz="0 1 0"/>
    <limit effort="30.0" lower="-1.4835298642" upper="1.4835298642" velocity="3.0"/>
  </joint>
  <joint name="r_ankle_roll" type="revolute">
    <parent link="r_ankle_pitch_link"/>
    <child link="r_ankle_roll_link"/>
    <origin rpy="0 0 0" xyz="0 0 0"/>
    <axis xyz="1 0 0"/>
    <limit effort="30.0" lower="-0.349065850399" upper="0.349065850399" velocity="3.0"/>
  </joint>
  <joint name="r_sole_joint" type="fixed">
    <parent link="r_ankle_roll_link"/>
    <child link="r_sole"/>
    <origin rpy="0 0 0" xyz="0 0 -0.124"/>
  </joint>
  <joint name="l_shoulder_pitch" type="revolute">
    <parent link="torso"/>
    <child link="l_shoulder_pitch_link"/>
    <origin rpy="0 0 0" xyz="-0.0 0.34 0.245"/>
    <axis xyz="0 1 0"/>
    <limit effort="30.0" lower="-3.14159265359" upper="3.14159265359" velocity="3.0"/>
  </joint>
  <joint name="l_shoulder_roll" type="revolute">
    <parent link="l_shoulder_pitch_link"/>
    <child link="l_shoulder_roll_link"/>
    <origin rpy="0 0 0" xyz="0 0 0"/>
    <axis xyz="1 0 0"/>
    <limit effort="30.0" lower="-0.785398163397" upper="2.09439510239" velocity="3.0"/>
  </joint>
  <joint name="l_shoulder_yaw" type="revolute">
    <parent link="l_shoulder_roll_link"/>
    <child link="l_shoulder_yaw_link"/>
    <origin rpy="0 0 0" xyz="0 0 0"/>
    <axis xyz="0 0 1"/>
    <limit effort="30.0" lower="-1.0471975512" upper="1.0471975512" velocity="3.0"/>
  </joint>
  <joint name="l_elbow_pitch" type="revolute">
    <parent link="l_shoulder_yaw_link"/>
    <child link="l_elbow_pitch_link"/>
    <origin rpy="0 0 0" xyz="0 0 -0.337"/>
    <axis xyz="0 1 0"/>
    <limit effort="30.0" lower="-1.74532925199" upper="1.74532925199" velocity="3.0"/>
  </joint>
  <joint name="l_wrist_yaw" type="revolute">
    <parent link="l_elbow_pitch_link"/>
    <child link="l_wrist_yaw_link"/>
    <origin rpy="0 0 0" xyz="0 0 -0.21"/>
    <axis xyz="0 0 1"/>
    <limit effort="30.0" lower="-0.698131700798" upper="0.959931088597" velocity="3.0"/>
  </joint>
  <joint name="l_wrist_pitch" type="revolute">
    <parent link="l_wrist_yaw_link"/>
    <child link="l_wrist_pitch_link"/>
    <origin rpy="0 0 0" xyz="0 0 0"/>
    <axis xyz="0 1 0"/>
    <limit effort="30.0" lower="-1.83259571459" upper="1.83259571459" velocity="3.0"/>
  </joint>
  <joint name="r_shoulder_pitch" type="revolute">
    <parent link="torso"/>
    <child link="r_shoulder_pitch_link"/>
    <origin rpy="0 0 0" xyz="-0.0 -0.34 0.245"/>
    <axis xyz="0 1 0"/>
    <limit effort="30.0" lower="-3.14159265359" upper="3.14159265359" velocity="3.0"/>
  </joint>
  <joint name="r_shoulder_roll" type="revolute">
    <parent link="r_shoulder_pitch_link"/>
    <child link="r_shoulder_roll_link"/>
    <origin rpy="0 0 0" xyz="0 0 0"/>
    <axis xyz="1 0 0"/>
    <limit effort="30.0" lower="-0.785398163397" upper="2.09439510239" velocity="3.0"/>
  </joint>
  <joint name="r_shoulder_yaw" type="revolute">
    <parent link="r_shoulder_roll_link"/>
    <child link="r_shoulder_yaw_link"/>
    <origin rpy="0 0 0" xyz="0 0 0"/>
    <axis xyz="0 0 1"/>
    <limit effort="30.0" lower="-1.0471975512" upper="1.0471975512" velocity="3.0"/>
  </joint>
  <joint name="r_elbow_pitch" type="revolute">
    <parent link="r_shoulder_yaw_link"/>
    <child link="r_elbow_pitch_link"/>
    <origin rpy="0 0 0" xyz="0 0 -0.337"/>
    <axis xyz="0 1 0"/>
    <limit effort="30.0" lower="-1.74532925199" upper="1.74532925199" velocity="3.0"/>
  </joint>
  <joint name="r_wrist_yaw" type="revolute">
    <parent link="r_elbow_pitch_link"/>
    <child link="r_wrist_yaw_link"/>
    <origin rpy="0 0 0" xyz="0 0 -0.21"/>
    <axis xyz="0 0 1"/>
    <limit effort="30.0" lower="-0.698131700798" upper="0.959931088597" velocity="3.0"/>
  </joint>
  <joint name="r_wrist_pitch" type="revolute">
    <parent link="r_wrist_yaw_link"/>
    <child link="r_wrist_pitch_link"/>
    <origin rpy="0 0 0" xyz="0 0 0"/>
    <axis xyz="0 1 0"/>
    <limit effort="30.0" lower="-1.83259571459" upper="1.83259571459" velocity="3.0"/>
  </joint>
  <joint name="base_joint" type="fixed">
    <child link="waist"/>
    <parent link="base_link"/>
    <origin rpy="0 0 0" xyz="0 0 0"/>
  </joint>
  <!--xacro:include filename="$(find teo_description)/urdf/simple_visual.xacro" /-->
  <material name="LightGrey">
    <color rgba="0.8 0.8 0.8 1.0"/>
  </material>
</robot>

