<?xml version="1.0" ?>
<!-- =================================================================================== -->
<!-- |    This document was autogenerated by xacro from teo_humanoid.urdf.xacro        | -->
<!-- |    EDITING THIS FILE BY HAND IS NOT RECOMMENDED                                 | -->
<!-- =================================================================================== -->
<robot name="teo" xmlns:xacro="http://ros.org/wiki/xacro">
  <!--
  ROS urdf definition of TEO humanoid robot
  
  Author: Domingo Esteban
  RoboticsLab, University Carlos III de Madrid
  
  This file loads TEO model with a basic visualization.

  If you want to convert this xacro file into an urdf file:
  $ rosrun xacro xacro.py teo_humanoid.urdf.xacro > teo_humanoid.urdf

	If you want to generate a SDF file from the generated URDF: (Requires gazebo)
	$ gzsdf print teo_humanoid.urdf > teo_humanoid.sdf
-->
  <link name="base_link"/>
  <link name="torso">
    <!--<inertial>
<origin xyz="0 0 0" rpy="0 0 0"/>
<mass value="1.0"/>
<inertia ixx="0.001" ixy="0.001" ixzv"0" iyy="0.001" iyz="0.001" izz="0.001" />
</inertial> -->
    <visual>
      <!-- one box -->
      <origin rpy="0 0 0" xyz="0 0 0.1"/>
      <geometry>
        <box size="0.18 0.42 0.292"/>
      </geometry>
      <material name="LightGrey"/>
    </visual>
    <collision>
      <origin rpy="0 0 0" xyz="0 0 0.1"/>
      <geometry>
        <box size="0.18 0.42 0.292"/>
      </geometry>
    </collision>
    <visual>
      <geometry>
        <box size="0.1 0.34 0.1"/>
      </geometry>
      <material name="grey"/>
      <origin rpy="0 0 0" xyz="0.0 -0.17 0.245"/>
    </visual>
    <collision>
      <geometry>
        <box size="0.1 0.34 0.1"/>
      </geometry>
      <origin rpy="0 0 0" xyz="0.0 -0.17 0.245"/>
    </collision>
    <visual>
      <geometry>
        <box size="0.1 0.34 0.1"/>
      </geometry>
      <material name="grey"/>
      <origin rpy="0 0 0" xyz="0.0 0.17 0.245"/>
    </visual>
    <collision>
      <geometry>
        <box size="0.1 0.34 0.1"/>
      </geometry>
      <origin rpy="0 0 0" xyz="0.0 0.17 0.245"/>
    </collision>
  </link>
  <link name="waist">
    <!--<inertial>
<origin xyz="0 0 0" rpy="0 0 0"/>
<mass value="1.0"/>
<inertia ixx="0.001" ixy="0.001" ixzv"0" iyy="0.001" iyz="0.001" izz="0.001" />
</inertial> -->
    <visual>
      <origin rpy="0 0 0" xyz="0 0 0.0905"/>
      <geometry>
        <box size="0.1 0.5 0.01"/>
      </geometry>
      <material name="LightGrey"/>
    </visual>
    <visual>
      <origin rpy="0 0 0" xyz="0 0 0.1755"/>
      <geometry>
        <cylinder length="0.15" radius="0.05"/>
      </geometry>
      <material name="LightGrey"/>
    </visual>
    <collision>
      <origin rpy="0 0 0" xyz="0 0 0.0905"/>
      <geometry>
        <box size="0.1 0.5 0.01"/>
      </geometry>
    </collision>
    <collision>
      <origin rpy="0 0 0" xyz="0 0 0.1755"/>
      <geometry>
        <cylinder length="0.15" radius="0.05"/>
      </geometry>
    </collision>
    <visual>
      <origin rpy="0 1.571 0" xyz="0 -0.146 0.045"/>
      <geometry>
        <cylinder length="0.13" radius="0.045"/>
      </geometry>
      <material name="LightGrey"/>
    </visual>
    <collision>
      <origin rpy="0 1.571 0" xyz="0 -0.146 0.045"/>
      <geometry>
        <cylinder length="0.13" radius="0.045"/>
      </geometry>
    </collision>
    <visual>
      <origin rpy="0 1.571 0" xyz="0 0.146 0.045"/>
      <geometry>
        <cylinder length="0.13" radius="0.045"/>
      </geometry>
      <material name="LightGrey"/>
    </visual>
    <collision>
      <origin rpy="0 1.571 0" xyz="0 0.146 0.045"/>
      <geometry>
        <cylinder length="0.13" radius="0.045"/>
      </geometry>
    </collision>
  </link>
  <link name="waist_yaw_link">
    <!--<inertial>
<origin xyz="0 0 0" rpy="0 0 0"/>
<mass value="1.0"/>
<inertia ixx="0.001" ixy="0.001" ixzv"0" iyy="0.001" iyz="0.001" izz="0.001" />
</inertial> -->
    <visual>
      <origin rpy="0 0 0" xyz="0 0 0.025"/>
      <geometry>
        <!--sphere radius="1.0"/-->
        <cylinder length="0.06" radius="0.02"/>
      </geometry>
      <material name="LightGrey"/>
    </visual>
    <collision>
      <origin rpy="0 0 0" xyz="0 0 0.025"/>
      <geometry>
        <!--sphere radius="1.0"/-->
        <cylinder length="0.06" radius="0.02"/>
      </geometry>
    </collision>
  </link>
  <link name="waist_pitch_link">
    <!--<inertial>
<origin xyz="0 0 0" rpy="0 0 0"/>
<mass value="1.0"/>
<inertia ixx="0.001" ixy="0.001" ixzv"0" iyy="0.001" iyz="0.001" izz="0.001" />
</inertial> -->
    <visual>
      <origin rpy="1.57079632679 0 0" xyz="0 0 0"/>
      <geometry>
        <!--sphere radius="1.0"/-->
        <cylinder length="0.06" radius="0.02"/>
      </geometry>
      <material name="LightGrey"/>
    </visual>
    <collision>
      <origin rpy="1.57079632679 0 0" xyz="0 0 0"/>
      <geometry>
        <!--sphere radius="1.0"/-->
        <cylinder length="0.06" radius="0.02"/>
      </geometry>
    </collision>
  </link>
  <link name="l_hip_yaw_link">
    <!--inertial>
<origin xyz="0.0 ${reflect*0.0} 0.0" rpy="0 0 0"/>
<mass value="1.0"/>
<inertia ixx="0.001" ixy="0.001" ixzv"0" iyy="0.001" iyz="0.001" izz="0.001" />
</inertial-->
  </link>
  <link name="l_hip_roll_link">
    <!--inertial>
<origin xyz="0.0 ${reflect*0.0} 0.0" rpy="0 0 0"/>
<mass value="1.0"/>
<inertia ixx="0.001" ixy="0.001" ixzv"0" iyy="0.001" iyz="0.001" izz="0.001" />
</inertial-->
    <xacro:insert_visualization_hip_roll reflect="{reflect}" side="l"/>
  </link>
  <link name="l_hip_pitch_link">
    <!--inertial>
<origin xyz="0.0 ${reflect*0.0} 0.0" rpy="0 0 0"/>
<mass value="1.0"/>
<inertia ixx="0.001" ixy="0.001" ixzv"0" iyy="0.001" iyz="0.001" izz="0.001" />
</inertial-->
    <visual>
      <geometry>
        <box size="0.1 0.1 0.33"/>
      </geometry>
      <material name="grey"/>
      <origin rpy="0 0 0" xyz="0 0 -0.165"/>
    </visual>
    <collision>
      <geometry>
        <box size="0.1 0.1 0.33"/>
      </geometry>
      <origin rpy="0 0 0" xyz="0 0 -0.165"/>
    </collision>
  </link>
  <link name="l_knee_pitch_link">
    <!--inertial>
<origin xyz="0.0 ${reflect*0.0} 0.0" rpy="0 0 0"/>
<mass value="1.0"/>
<inertia ixx="0.001" ixy="0.001" ixzv"0" iyy="0.001" iyz="0.001" izz="0.001" />
</inertial-->
    <visual>
      <geometry>
        <box size="0.08 0.08 0.3"/>
      </geometry>
      <material name="grey"/>
      <origin rpy="0 0 0" xyz="0 0 -0.15"/>
    </visual>
    <visual>
      <geometry>
        <box size="0.05 0.033 0.05"/>
      </geometry>
      <material name="grey"/>
      <origin rpy="0 0 0" xyz="0 -0.033 -0.275"/>
    </visual>
    <collision>
      <geometry>
        <box size="0.08 0.08 0.3"/>
      </geometry>
      <origin rpy="0 0 0" xyz="0 0 -0.15"/>
    </collision>
    <collision>
      <geometry>
        <box size="0.05 0.033 0.05"/>
      </geometry>
      <origin rpy="0 0 0" xyz="0 -0.033 -0.275"/>
    </collision>
  </link>
  <link name="l_ankle_pitch_link">
    <!--inertial>
<origin xyz="0.0 ${reflect*0.0} 0.0" rpy="0 0 0"/>
<mass value="1.0"/>
<inertia ixx="0.001" ixy="0.001" ixzv"0" iyy="0.001" iyz="0.001" izz="0.001" />
</inertial-->
  </link>
  <link name="l_ankle_roll_link">
    <!--inertial>
<origin xyz="0.0 ${reflect*0.0} 0.0" rpy="0 0 0"/>
<mass value="1.0"/>
<inertia ixx="0.001" ixy="0.001" ixzv"0" iyy="0.001" iyz="0.001" izz="0.001" />
</inertial-->
    <visual>
      <geometry>
        <box size="0.08 0.08 0.124"/>
      </geometry>
      <material name="grey"/>
      <origin rpy="0 0 0" xyz="0 0 -0.062"/>
    </visual>
    <collision>
      <geometry>
        <box size="0.08 0.08 0.124"/>
      </geometry>
      <origin rpy="0 0 0" xyz="0 0 -0.062"/>
    </collision>
    <visual>
      <geometry>
        <box size="0.2 0.1 0.01"/>
      </geometry>
      <material name="grey"/>
      <origin rpy="0 0 0" xyz="0.05 0 -0.129"/>
    </visual>
    <collision>
      <geometry>
        <box size="0.2 0.1 0.01"/>
      </geometry>
      <origin rpy="0 0 0" xyz="0.05 0 -0.129"/>
    </collision>
    <!-- OJO, falta bajarlo -link5/2-->
  </link>
  <link name="l_sole">
    <!--inertial>
<origin xyz="0.0 ${reflect*0.0} 0.0" rpy="0 0 0"/>
<mass value="1.0"/>
<inertia ixx="0.001" ixy="0.001" ixzv"0" iyy="0.001" iyz="0.001" izz="0.001" />
</inertial-->
  </link>
  <link name="r_hip_yaw_link">
    <!--inertial>
<origin xyz="0.0 ${reflect*0.0} 0.0" rpy="0 0 0"/>
<mass value="1.0"/>
<inertia ixx="0.001" ixy="0.001" ixzv"0" iyy="0.001" iyz="0.001" izz="0.001" />
</inertial-->
  </link>
  <link name="r_hip_roll_link">
    <!--inertial>
<origin xyz="0.0 ${reflect*0.0} 0.0" rpy="0 0 0"/>
<mass value="1.0"/>
<inertia ixx="0.001" ixy="0.001" ixzv"0" iyy="0.001" iyz="0.001" izz="0.001" />
</inertial-->
    <xacro:insert_visualization_hip_roll reflect="{reflect}" side="r"/>
  </link>
  <link name="r_hip_pitch_link">
    <!--inertial>
<origin xyz="0.0 ${reflect*0.0} 0.0" rpy="0 0 0"/>
<mass value="1.0"/>
<inertia ixx="0.001" ixy="0.001" ixzv"0" iyy="0.001" iyz="0.001" izz="0.001" />
</inertial-->
    <visual>
      <geometry>
        <box size="0.1 0.1 0.33"/>
      </geometry>
      <material name="grey"/>
      <origin rpy="0 0 0" xyz="0 0 -0.165"/>
    </visual>
    <collision>
      <geometry>
        <box size="0.1 0.1 0.33"/>
      </geometry>
      <origin rpy="0 0 0" xyz="0 0 -0.165"/>
    </collision>
  </link>
  <link name="r_knee_pitch_link">
    <!--inertial>
<origin xyz="0.0 ${reflect*0.0} 0.0" rpy="0 0 0"/>
<mass value="1.0"/>
<inertia ixx="0.001" ixy="0.001" ixzv"0" iyy="0.001" iyz="0.001" izz="0.001" />
</inertial-->
    <visual>
      <geometry>
        <box size="0.08 0.08 0.3"/>
      </geometry>
      <material name="grey"/>
      <origin rpy="0 0 0" xyz="0 0 -0.15"/>
    </visual>
    <visual>
      <geometry>
        <box size="0.05 0.033 0.05"/>
      </geometry>
      <material name="grey"/>
      <origin rpy="0 0 0" xyz="0 0.033 -0.275"/>
    </visual>
    <collision>
      <geometry>
        <box size="0.08 0.08 0.3"/>
      </geometry>
      <origin rpy="0 0 0" xyz="0 0 -0.15"/>
    </collision>
    <collision>
      <geometry>
        <box size="0.05 0.033 0.05"/>
      </geometry>
      <origin rpy="0 0 0" xyz="0 0.033 -0.275"/>
    </collision>
  </link>
  <link name="r_ankle_pitch_link">
    <!--inertial>
<origin xyz="0.0 ${reflect*0.0} 0.0" rpy="0 0 0"/>
<mass value="1.0"/>
<inertia ixx="0.001" ixy="0.001" ixzv"0" iyy="0.001" iyz="0.001" izz="0.001" />
</inertial-->
  </link>
  <link name="r_ankle_roll_link">
    <!--inertial>
<origin xyz="0.0 ${reflect*0.0} 0.0" rpy="0 0 0"/>
<mass value="1.0"/>
<inertia ixx="0.001" ixy="0.001" ixzv"0" iyy="0.001" iyz="0.001" izz="0.001" />
</inertial-->
    <visual>
      <geometry>
        <box size="0.08 0.08 0.124"/>
      </geometry>
      <material name="grey"/>
      <origin rpy="0 0 0" xyz="0 0 -0.062"/>
    </visual>
    <collision>
      <geometry>
        <box size="0.08 0.08 0.124"/>
      </geometry>
      <origin rpy="0 0 0" xyz="0 0 -0.062"/>
    </collision>
    <visual>
      <geometry>
        <box size="0.2 0.1 0.01"/>
      </geometry>
      <material name="grey"/>
      <origin rpy="0 0 0" xyz="0.05 0 -0.129"/>
    </visual>
    <collision>
      <geometry>
        <box size="0.2 0.1 0.01"/>
      </geometry>
      <origin rpy="0 0 0" xyz="0.05 0 -0.129"/>
    </collision>
    <!-- OJO, falta bajarlo -link5/2-->
  </link>
  <link name="r_sole">
    <!--inertial>
<origin xyz="0.0 ${reflect*0.0} 0.0" rpy="0 0 0"/>
<mass value="1.0"/>
<inertia ixx="0.001" ixy="0.001" ixzv"0" iyy="0.001" iyz="0.001" izz="0.001" />
</inertial-->
  </link>
  <link name="l_shoulder_pitch_link">
    <!--inertial>
<origin xyz="0.0 ${reflect*0.0} 0.0" rpy="0 0 0"/>
<mass value="1.0"/>
<inertia ixx="0.001" ixy="0.001" ixzv"0" iyy="0.001" iyz="0.001" izz="0.001" />
</inertial-->
  </link>
  <link name="l_shoulder_roll_link">
    <!--inertial>
<origin xyz="0.0 ${reflect*0.0} 0.0" rpy="0 0 0"/>
<mass value="1.0"/>
<inertia ixx="0.001" ixy="0.001" ixzv"0" iyy="0.001" iyz="0.001" izz="0.001" />
</inertial-->
  </link>
  <link name="l_shoulder_yaw_link">
    <!--inertial>
<origin xyz="0.0 ${reflect*0.0} 0.0" rpy="0 0 0"/>
<mass value="1.0"/>
<inertia ixx="0.001" ixy="0.001" ixzv"0" iyy="0.001" iyz="0.001" izz="0.001" />
</inertial-->
    <visual>
      <geometry>
        <box size="0.08 0.08 0.337"/>
      </geometry>
      <material name="grey"/>
      <origin rpy="0 0 0" xyz="0 0 -0.1685"/>
    </visual>
    <collision>
      <geometry>
        <box size="0.08 0.08 0.337"/>
      </geometry>
      <origin rpy="0 0 0" xyz="0 0 -0.1685"/>
    </collision>
  </link>
  <link name="l_elbow_pitch_link">
    <!--inertial>
<origin xyz="0.0 ${reflect*0.0} 0.0" rpy="0 0 0"/>
<mass value="1.0"/>
<inertia ixx="0.001" ixy="0.001" ixzv"0" iyy="0.001" iyz="0.001" izz="0.001" />
</inertial-->
    <visual>
      <geometry>
        <box size="0.06 0.06 0.21"/>
      </geometry>
      <material name="grey"/>
      <origin rpy="0 0 0" xyz="0 0 -0.105"/>
    </visual>
    <collision>
      <geometry>
        <box size="0.06 0.06 0.21"/>
      </geometry>
      <origin rpy="0 0 0" xyz="0 0 -0.105"/>
    </collision>
  </link>
  <link name="l_wrist_yaw_link">
    <!--inertial>
<origin xyz="0.0 ${reflect*0.0} 0.0" rpy="0 0 0"/>
<mass value="1.0"/>
<inertia ixx="0.001" ixy="0.001" ixzv"0" iyy="0.001" iyz="0.001" izz="0.001" />
</inertial-->
  </link>
  <link name="l_wrist_pitch_link">
    <!--inertial>
<origin xyz="0.0 ${reflect*0.0} 0.0" rpy="0 0 0"/>
<mass value="1.0"/>
<inertia ixx="0.001" ixy="0.001" ixzv"0" iyy="0.001" iyz="0.001" izz="0.001" />
</inertial-->
  </link>
  <link name="r_shoulder_pitch_link">
    <!--inertial>
<origin xyz="0.0 ${reflect*0.0} 0.0" rpy="0 0 0"/>
<mass value="1.0"/>
<inertia ixx="0.001" ixy="0.001" ixzv"0" iyy="0.001" iyz="0.001" izz="0.001" />
</inertial-->
  </link>
  <link name="r_shoulder_roll_link">
    <!--inertial>
<origin xyz="0.0 ${reflect*0.0} 0.0" rpy="0 0 0"/>
<mass value="1.0"/>
<inertia ixx="0.001" ixy="0.001" ixzv"0" iyy="0.001" iyz="0.001" izz="0.001" />
</inertial-->
  </link>
  <link name="r_shoulder_yaw_link">
    <!--inertial>
<origin xyz="0.0 ${reflect*0.0} 0.0" rpy="0 0 0"/>
<mass value="1.0"/>
<inertia ixx="0.001" ixy="0.001" ixzv"0" iyy="0.001" iyz="0.001" izz="0.001" />
</inertial-->
    <visual>
      <geometry>
        <box size="0.08 0.08 0.337"/>
      </geometry>
      <material name="grey"/>
      <origin rpy="0 0 0" xyz="0 0 -0.1685"/>
    </visual>
    <collision>
      <geometry>
        <box size="0.08 0.08 0.337"/>
      </geometry>
      <origin rpy="0 0 0" xyz="0 0 -0.1685"/>
    </collision>
  </link>
  <link name="r_elbow_pitch_link">
    <!--inertial>
<origin xyz="0.0 ${reflect*0.0} 0.0" rpy="0 0 0"/>
<mass value="1.0"/>
<inertia ixx="0.001" ixy="0.001" ixzv"0" iyy="0.001" iyz="0.001" izz="0.001" />
</inertial-->
    <visual>
      <geometry>
        <box size="0.06 0.06 0.21"/>
      </geometry>
      <material name="grey"/>
      <origin rpy="0 0 0" xyz="0 0 -0.105"/>
    </visual>
    <collision>
      <geometry>
        <box size="0.06 0.06 0.21"/>
      </geometry>
      <origin rpy="0 0 0" xyz="0 0 -0.105"/>
    </collision>
  </link>
  <link name="r_wrist_yaw_link">
    <!--inertial>
<origin xyz="0.0 ${reflect*0.0} 0.0" rpy="0 0 0"/>
<mass value="1.0"/>
<inertia ixx="0.001" ixy="0.001" ixzv"0" iyy="0.001" iyz="0.001" izz="0.001" />
</inertial-->
  </link>
  <link name="r_wrist_pitch_link">
    <!--inertial>
<origin xyz="0.0 ${reflect*0.0} 0.0" rpy="0 0 0"/>
<mass value="1.0"/>
<inertia ixx="0.001" ixy="0.001" ixzv"0" iyy="0.001" iyz="0.001" izz="0.001" />
</inertial-->
  </link>
  <joint name="waist_yaw" type="revolute">
    <parent link="waist"/>
    <child link="waist_yaw_link"/>
    <origin rpy="0 0 0" xyz="0.0 0 0.287"/>
    <axis xyz="0 0 1"/>
    <limit effort="30.0" lower="-1.57079632679" upper="1.57079632679" velocity="3.0"/>
  </joint>
  <joint name="waist_pitch" type="revolute">
    <parent link="waist_yaw_link"/>
    <child link="waist_pitch_link"/>
    <origin rpy="0 0 0" xyz="-0.0 0 0"/>
    <axis xyz="0 1 0"/>
    <limit effort="30.0" lower="0.0" upper="0.785398163397" velocity="3.0"/>
  </joint>
  <joint name="torso_joint" type="fixed">
    <parent link="waist_pitch_link"/>
    <child link="torso"/>
    <origin rpy="0 0 0" xyz="0 0 0.06"/>
  </joint>
  <joint name="l_hip_yaw" type="revolute">
    <parent link="waist"/>
    <child link="l_hip_yaw_link"/>
    <origin rpy="0 0 0" xyz="0 0.146 0"/>
    <!--y=Leg_link1-->
    <axis xyz="0 0 1"/>
    <limit effort="30.0" lower="-0.52359878756" upper="0.418879020479" velocity="3.0"/>
  </joint>
  <joint name="l_hip_roll" type="revolute">
    <parent link="l_hip_yaw_link"/>
    <child link="l_hip_roll_link"/>
    <origin rpy="0 0 0" xyz="0 0 0"/>
    <axis xyz="1 0 0"/>
    <limit effort="30.0" lower="-2.09439510239" upper="0.785398163397" velocity="3.0"/>
  </joint>
  <joint name="l_hip_pitch" type="revolute">
    <parent link="l_hip_roll_link"/>
    <child link="l_hip_pitch_link"/>
    <origin rpy="0 0 0" xyz="0 0 0"/>
    <axis xyz="0 1 0"/>
    <limit effort="30.0" lower="-0.698131700798" upper="0.523598775598" velocity="3.0"/>
  </joint>
  <joint name="l_knee_pitch" type="revolute">
    <parent link="l_hip_pitch_link"/>
    <child link="l_knee_pitch_link"/>
    <origin rpy="0 0 0" xyz="0 0 -0.33"/>
    <axis xyz="0 1 0"/>
    <limit effort="30.0" lower="0.0" upper="1.57079632679" velocity="3.0"/>
  </joint>
  <joint name="l_ankle_pitch" type="revolute">
    <parent link="l_knee_pitch_link"/>
    <child link="l_ankle_pitch_link"/>
    <origin rpy="0 0 0" xyz="0 -0.033 -0.3"/>
    <axis xyz="0 1 0"/>
    <limit effort="30.0" lower="-1.4835298642" upper="1.4835298642" velocity="3.0"/>
  </joint>
  <joint name="l_ankle_roll" type="revolute">
    <parent link="l_ankle_pitch_link"/>
    <child link="l_ankle_roll_link"/>
    <origin rpy="0 0 0" xyz="0 0 0"/>
    <axis xyz="1 0 0"/>
    <limit effort="30.0" lower="-0.349065850399" upper="0.349065850399" velocity="3.0"/>
  </joint>
  <joint name="l_sole_joint" type="fixed">
    <parent link="l_ankle_roll_link"/>
    <child link="l_sole"/>
    <origin rpy="0 0 0" xyz="0 0 -0.124"/>
  </joint>
  <joint name="r_hip_yaw" type="revolute">
    <parent link="waist"/>
    <child link="r_hip_yaw_link"/>
    <origin rpy="0 0 0" xyz="0 -0.146 0"/>
    <!--y=Leg_link1-->
    <axis xyz="0 0 1"/>
    <limit effort="30.0" lower="-0.52359878756" upper="0.418879020479" velocity="3.0"/>
  </joint>
  <joint name="r_hip_roll" type="revolute">
    <parent link="r_hip_yaw_link"/>
    <child link="r_hip_roll_link"/>
    <origin rpy="0 0 0" xyz="0 0 0"/>
    <axis xyz="1 0 0"/>
    <limit effort="30.0" lower="-2.09439510239" upper="0.785398163397" velocity="3.0"/>
  </joint>
  <joint name="r_hip_pitch" type="revolute">
    <parent link="r_hip_roll_link"/>
    <child link="r_hip_pitch_link"/>
    <origin rpy="0 0 0" xyz="0 0 0"/>
    <axis xyz="0 1 0"/>
    <limit effort="30.0" lower="-0.698131700798" upper="0.523598775598" velocity="3.0"/>
  </joint>
  <joint name="r_knee_pitch" type="revolute">
    <parent link="r_hip_pitch_link"/>
    <child link="r_knee_pitch_link"/>
    <origin rpy="0 0 0" xyz="0 0 -0.33"/>
    <axis xyz="0 1 0"/>
    <limit effort="30.0" lower="0.0" upper="1.57079632679" velocity="3.0"/>
  </joint>
  <joint name="r_ankle_pitch" type="revolute">
    <parent link="r_knee_pitch_link"/>
    <child link="r_ankle_pitch_link"/>
    <origin rpy="0 0 0" xyz="0 0.033 -0.3"/>
    <axis xyz="0 1 0"/>
    <limit effort="30.0" lower="-1.4835298642" upper="1.4835298642" velocity="3.0"/>
  </joint>
  <joint name="r_ankle_roll" type="revolute">
    <parent link="r_ankle_pitch_link"/>
    <child link="r_ankle_roll_link"/>
    <origin rpy="0 0 0" xyz="0 0 0"/>
    <axis xyz="1 0 0"/>
    <limit effort="30.0" lower="-0.349065850399" upper="0.349065850399" velocity="3.0"/>
  </joint>
  <joint name="r_sole_joint" type="fixed">
    <parent link="r_ankle_roll_link"/>
    <child link="r_sole"/>
    <origin rpy="0 0 0" xyz="0 0 -0.124"/>
  </joint>
  <joint name="l_shoulder_pitch" type="revolute">
    <parent link="torso"/>
    <child link="l_shoulder_pitch_link"/>
    <origin rpy="0 0 0" xyz="-0.0 0.34 0.245"/>
    <axis xyz="0 1 0"/>
    <limit effort="30.0" lower="-3.14159265359" upper="3.14159265359" velocity="3.0"/>
  </joint>
  <joint name="l_shoulder_roll" type="revolute">
    <parent link="l_shoulder_pitch_link"/>
    <child link="l_shoulder_roll_link"/>
    <origin rpy="0 0 0" xyz="0 0 0"/>
    <axis xyz="1 0 0"/>
    <limit effort="30.0" lower="-0.785398163397" upper="2.09439510239" velocity="3.0"/>
  </joint>
  <joint name="l_shoulder_yaw" type="revolute">
    <parent link="l_shoulder_roll_link"/>
    <child link="l_shoulder_yaw_link"/>
    <origin rpy="0 0 0" xyz="0 0 0"/>
    <axis xyz="0 0 1"/>
    <limit effort="30.0" lower="-1.0471975512" upper="1.0471975512" velocity="3.0"/>
  </joint>
  <joint name="l_elbow_pitch" type="revolute">
    <parent link="l_shoulder_yaw_link"/>
    <child link="l_elbow_pitch_link"/>
    <origin rpy="0 0 0" xyz="0 0 -0.337"/>
    <axis xyz="0 1 0"/>
    <limit effort="30.0" lower="-1.74532925199" upper="1.74532925199" velocity="3.0"/>
  </joint>
  <joint name="l_wrist_yaw" type="revolute">
    <parent link="l_elbow_pitch_link"/>
    <child link="l_wrist_yaw_link"/>
    <origin rpy="0 0 0" xyz="0 0 -0.21"/>
    <axis xyz="0 0 1"/>
    <limit effort="30.0" lower="-0.698131700798" upper="0.959931088597" velocity="3.0"/>
  </joint>
  <joint name="l_wrist_pitch" type="revolute">
    <parent link="l_wrist_yaw_link"/>
    <child link="l_wrist_pitch_link"/>
    <origin rpy="0 0 0" xyz="0 0 0"/>
    <axis xyz="0 1 0"/>
    <limit effort="30.0" lower="-1.83259571459" upper="1.83259571459" velocity="3.0"/>
  </joint>
  <joint name="r_shoulder_pitch" type="revolute">
    <parent link="torso"/>
    <child link="r_shoulder_pitch_link"/>
    <origin rpy="0 0 0" xyz="-0.0 -0.34 0.245"/>
    <axis xyz="0 1 0"/>
    <limit effort="30.0" lower="-3.14159265359" upper="3.14159265359" velocity="3.0"/>
  </joint>
  <joint name="r_shoulder_roll" type="revolute">
    <parent link="r_shoulder_pitch_link"/>
    <child link="r_shoulder_roll_link"/>
    <origin rpy="0 0 0" xyz="0 0 0"/>
    <axis xyz="1 0 0"/>
    <limit effort="30.0" lower="-0.785398163397" upper="2.09439510239" velocity="3.0"/>
  </joint>
  <joint name="r_shoulder_yaw" type="revolute">
    <parent link="r_shoulder_roll_link"/>
    <child link="r_shoulder_yaw_link"/>
    <origin rpy="0 0 0" xyz="0 0 0"/>
    <axis xyz="0 0 1"/>
    <limit effort="30.0" lower="-1.0471975512" upper="1.0471975512" velocity="3.0"/>
  </joint>
  <joint name="r_elbow_pitch" type="revolute">
    <parent link="r_shoulder_yaw_link"/>
    <child link="r_elbow_pitch_link"/>
    <origin rpy="0 0 0" xyz="0 0 -0.337"/>
    <axis xyz="0 1 0"/>
    <limit effort="30.0" lower="-1.74532925199" upper="1.74532925199" velocity="3.0"/>
  </joint>
  <joint name="r_wrist_yaw" type="revolute">
    <parent link="r_elbow_pitch_link"/>
    <child link="r_wrist_yaw_link"/>
    <origin rpy="0 0 0" xyz="0 0 -0.21"/>
    <axis xyz="0 0 1"/>
    <limit effort="30.0" lower="-0.698131700798" upper="0.959931088597" velocity="3.0"/>
  </joint>
  <joint name="r_wrist_pitch" type="revolute">
    <parent link="r_wrist_yaw_link"/>
    <child link="r_wrist_pitch_link"/>
    <origin rpy="0 0 0" xyz="0 0 0"/>
    <axis xyz="0 1 0"/>
    <limit effort="30.0" lower="-1.83259571459" upper="1.83259571459" velocity="3.0"/>
  </joint>
  <joint name="base_joint" type="fixed">
    <child link="waist"/>
    <parent link="base_link"/>
    <origin rpy="0 0 0" xyz="0 0 0"/>
  </joint>
  <material name="LightGrey">
    <color rgba="0.8 0.8 0.8 1.0"/>
  </material>
  <!--xacro:include filename="$(find teo_description)/urdf/complete_visual.xacro" /-->
</robot>

