<?xml version="1.0" ?>
<!-- =================================================================================== -->
<!-- |    This document was autogenerated by xacro from teo_humanoid_simple_vis.urdf.xacro | -->
<!-- |    EDITING THIS FILE BY HAND IS NOT RECOMMENDED                                 | -->
<!-- =================================================================================== -->
<!--
  ROS urdf definition of TEO humanoid robot
  
  Author: Domingo Esteban
  RoboticsLab, Universidad Carlos III de Madrid
  
  This file loads TEO model with a basic visualization.

  If you want to convert this xacro file into an urdf file:
  $ rosrun xacro xacro.py teo_humanoid_simple_vis.urdf.xacro > teo_humanoid.urdf

	If you want to generate a SDF file from the generated URDF: (Requires gazebo)
	$ gzsdf print teo_humanoid.urdf > teo_humanoid.sdf
-->
<robot name="teo" xmlns:xacro="http://ros.org/wiki/xacro">
  <!-- TEO structure -->
  <link name="base_link"/>
  <joint name="base_joint" type="fixed">
    <child link="waist"/>
    <parent link="base_link"/>
    <origin rpy="0 0 0" xyz="0 0 0"/>
  </joint>
  <link name="waist">
    <inertial>
      <origin rpy="0 0 0" xyz="0.0 0.0 0.0337"/>
      <mass value="25.7044"/>
      <inertia ixx="0.019" ixy="0.000" ixz="0.000" iyy="0.018" iyz="0.000" izz="0.008"/>
    </inertial>
    <xacro:insert_visualization_waist/>
    <visual>
      <origin rpy="0 1.571 0" xyz="0 -0.146 0.045"/>
      <geometry>
        <cylinder length="0.13" radius="0.045"/>
      </geometry>
      <material name="LightGrey"/>
    </visual>
    <collision>
      <origin rpy="0 1.571 0" xyz="0 -0.146 0.045"/>
      <geometry>
        <cylinder length="0.13" radius="0.045"/>
      </geometry>
    </collision>
    <visual>
      <origin rpy="0 1.571 0" xyz="0 0.146 0.045"/>
      <geometry>
        <cylinder length="0.13" radius="0.045"/>
      </geometry>
      <material name="LightGrey"/>
    </visual>
    <collision>
      <origin rpy="0 1.571 0" xyz="0 0.146 0.045"/>
      <geometry>
        <cylinder length="0.13" radius="0.045"/>
      </geometry>
    </collision>
  </link>
  <link name="waist_yaw_link">
    <inertial>
      <origin rpy="0 0 0" xyz="0 0 0"/>
      <mass value="0.1"/>
      <inertia ixx="1.000" ixy="0.000" ixz="0.000" iyy="1.000" iyz="0.000" izz="1.000"/>
    </inertial>
    <visual>
      <origin rpy="0 0 0" xyz="0 0 0.025"/>
      <geometry>
        <!--sphere radius="1.0"/-->
        <cylinder length="0.06" radius="0.02"/>
      </geometry>
      <material name="LightGrey"/>
    </visual>
    <collision>
      <origin rpy="0 0 0" xyz="0 0 0.025"/>
      <geometry>
        <!--sphere radius="1.0"/-->
        <cylinder length="0.06" radius="0.02"/>
      </geometry>
    </collision>
  </link>
  <link name="waist_pitch_link">
    <inertial>
      <origin rpy="0 0 0" xyz="0 0 0"/>
      <mass value="1.0"/>
      <inertia ixx="1.000" ixy="0.000" ixz="0.000" iyy="1.000" iyz="0.000" izz="1.000"/>
    </inertial>
    <visual>
      <origin rpy="1.57079632679 0 0" xyz="0 0 0"/>
      <geometry>
        <!--sphere radius="1.0"/-->
        <cylinder length="0.06" radius="0.02"/>
      </geometry>
      <material name="LightGrey"/>
    </visual>
    <collision>
      <origin rpy="1.57079632679 0 0" xyz="0 0 0"/>
      <geometry>
        <!--sphere radius="1.0"/-->
        <cylinder length="0.06" radius="0.02"/>
      </geometry>
    </collision>
    <visual>
      <!-- one box -->
      <origin rpy="0 0 0" xyz="0 0 0.1"/>
      <geometry>
        <box size="0.18 0.42 0.292"/>
      </geometry>
      <material name="LightGrey"/>
    </visual>
    <collision>
      <origin rpy="0 0 0" xyz="0 0 0.1"/>
      <geometry>
        <box size="0.18 0.42 0.292"/>
      </geometry>
    </collision>
  </link>
  <joint name="waist_yaw" type="revolute">
    <parent link="waist"/>
    <child link="waist_yaw_link"/>
    <origin rpy="0 0 0" xyz="0.0 0 0.287"/>
    <axis xyz="0 0 1"/>
    <limit effort="30.0" lower="-0.785398163397" upper="0.523598775598" velocity="3.0"/>
  </joint>
  <joint name="waist_pitch" type="revolute">
    <parent link="waist_yaw_link"/>
    <child link="waist_pitch_link"/>
    <origin rpy="0 0 0" xyz="-0.0 0 0"/>
    <axis xyz="0 1 0"/>
    <limit effort="30.0" lower="-0.785398163397" upper="0.523598775598" velocity="3.0"/>
  </joint>
  <transmission name="waist_yaw_trans">
    <type>transmission_interface/SimpleTransmission</type>
    <joint name="waist_yaw"/>
    <actuator name="waist_yaw_motor">
      <hardwareInterface>EffortJointInterface</hardwareInterface>
      <mechanicalReduction>1.0</mechanicalReduction>
    </actuator>
  </transmission>
  <transmission name="waist_pitch_trans">
    <type>transmission_interface/SimpleTransmission</type>
    <joint name="waist_pitch"/>
    <actuator name="waist_pitch_motor">
      <hardwareInterface>EffortJointInterface</hardwareInterface>
      <mechanicalReduction>1.0</mechanicalReduction>
    </actuator>
  </transmission>
  <link name="l_hip_yaw_link">
    <inertial>
      <origin rpy="0 0 0" xyz="0.0 0.0 0.0"/>
      <mass value="0.001"/>
      <inertia ixx="1.000" ixy="0.000" ixz="0.000" iyy="1.000" iyz="0.000" izz="1.000"/>
    </inertial>
  </link>
  <link name="l_hip_roll_link">
    <inertial>
      <origin rpy="0 0 0" xyz="0.0 0.0 0.0"/>
      <mass value="0.001"/>
      <inertia ixx="1.000" ixy="0.000" ixz="0.000" iyy="1.000" iyz="0.000" izz="1.000"/>
    </inertial>
    <xacro:insert_visualization_hip_roll reflect="{reflect}" side="l"/>
  </link>
  <link name="l_femur_link">
    <inertial>
      <origin rpy="0 0 0" xyz="0.033 0.034 0.187"/>
      <mass value="1.844"/>
      <inertia ixx="0.020" ixy="6.052e-5" ixz="7.948e-4" iyy="0.025" iyz="6.454e-4" izz="0.013"/>
    </inertial>
    <visual>
      <geometry>
        <box size="0.1 0.1 0.33"/>
      </geometry>
      <material name="grey"/>
      <origin rpy="0 0 0" xyz="0 0 -0.165"/>
    </visual>
    <collision>
      <geometry>
        <box size="0.1 0.1 0.33"/>
      </geometry>
      <origin rpy="0 0 0" xyz="0 0 -0.165"/>
    </collision>
  </link>
  <link name="l_tibia_link">
    <inertial>
      <origin rpy="0 0 0" xyz="-0.027 0.028 0.13632"/>
      <mass value="2.0817"/>
      <inertia ixx="0.020" ixy="6.052e-5" ixz="-7.498e-4" iyy="0.025" iyz="6.454e-4" izz="0.013"/>
    </inertial>
    <visual>
      <geometry>
        <box size="0.08 0.08 0.3"/>
      </geometry>
      <material name="grey"/>
      <origin rpy="0 0 0" xyz="0 0 -0.15"/>
    </visual>
    <visual>
      <geometry>
        <box size="0.05 0.033 0.05"/>
      </geometry>
      <material name="grey"/>
      <origin rpy="0 0 0" xyz="0 -0.033 -0.275"/>
    </visual>
    <collision>
      <geometry>
        <box size="0.08 0.08 0.3"/>
      </geometry>
      <origin rpy="0 0 0" xyz="0 0 -0.15"/>
    </collision>
    <collision>
      <geometry>
        <box size="0.05 0.033 0.05"/>
      </geometry>
      <origin rpy="0 0 0" xyz="0 -0.033 -0.275"/>
    </collision>
  </link>
  <link name="l_ankle_pitch_link">
    <inertial>
      <origin rpy="0 0 0" xyz="0.0 0.0 0.0"/>
      <mass value="1.0"/>
      <inertia ixx="1.000" ixy="0.000" ixz="0.000" iyy="1.000" iyz="0.000" izz="1.000"/>
    </inertial>
  </link>
  <link name="l_astragalus_link">
    <inertial>
      <origin rpy="0 0 0" xyz="3.026e-3 0.0035 -9.323e-3"/>
      <mass value="3.8994"/>
      <inertia ixx="0.062" ixy="-1.417e-4" ixz="-0.004" iyy="0.059" iyz="0.002" izz="0.011"/>
    </inertial>
    <visual>
      <geometry>
        <box size="0.08 0.08 0.124"/>
      </geometry>
      <material name="grey"/>
      <origin rpy="0 0 0" xyz="0 0 -0.062"/>
    </visual>
    <collision>
      <geometry>
        <box size="0.08 0.08 0.124"/>
      </geometry>
      <origin rpy="0 0 0" xyz="0 0 -0.062"/>
    </collision>
    <visual>
      <geometry>
        <box size="0.2 0.1 0.01"/>
      </geometry>
      <material name="grey"/>
      <origin rpy="0 0 0" xyz="0.05 0 -0.129"/>
    </visual>
    <collision>
      <geometry>
        <box size="0.2 0.1 0.01"/>
      </geometry>
      <origin rpy="0 0 0" xyz="0.05 0 -0.129"/>
    </collision>
    <!-- OJO, falta bajarlo -link5/2-->
  </link>
  <link name="l_sole">
    <inertial>
      <origin rpy="0 0 0" xyz="0.0 0.0 0.0"/>
      <mass value="0.001"/>
      <inertia ixx="1.000" ixy="0.000" ixz="0.000" iyy="1.000" iyz="0.000" izz="1.000"/>
    </inertial>
  </link>
  <link name="r_hip_yaw_link">
    <inertial>
      <origin rpy="0 0 0" xyz="0.0 -0.0 0.0"/>
      <mass value="0.001"/>
      <inertia ixx="1.000" ixy="0.000" ixz="0.000" iyy="1.000" iyz="0.000" izz="1.000"/>
    </inertial>
  </link>
  <link name="r_hip_roll_link">
    <inertial>
      <origin rpy="0 0 0" xyz="0.0 -0.0 0.0"/>
      <mass value="0.001"/>
      <inertia ixx="1.000" ixy="0.000" ixz="0.000" iyy="1.000" iyz="0.000" izz="1.000"/>
    </inertial>
    <xacro:insert_visualization_hip_roll reflect="{reflect}" side="r"/>
  </link>
  <link name="r_femur_link">
    <inertial>
      <origin rpy="0 0 0" xyz="0.033 -0.032 0.187"/>
      <mass value="1.844"/>
      <inertia ixx="0.020" ixy="6.052e-5" ixz="7.948e-4" iyy="0.025" iyz="6.454e-4" izz="0.013"/>
    </inertial>
    <visual>
      <geometry>
        <box size="0.1 0.1 0.33"/>
      </geometry>
      <material name="grey"/>
      <origin rpy="0 0 0" xyz="0 0 -0.165"/>
    </visual>
    <collision>
      <geometry>
        <box size="0.1 0.1 0.33"/>
      </geometry>
      <origin rpy="0 0 0" xyz="0 0 -0.165"/>
    </collision>
  </link>
  <link name="r_tibia_link">
    <inertial>
      <origin rpy="0 0 0" xyz="-0.027 -0.038 0.13632"/>
      <mass value="2.0817"/>
      <inertia ixx="0.020" ixy="6.052e-5" ixz="-7.498e-4" iyy="0.025" iyz="6.454e-4" izz="0.013"/>
    </inertial>
    <visual>
      <geometry>
        <box size="0.08 0.08 0.3"/>
      </geometry>
      <material name="grey"/>
      <origin rpy="0 0 0" xyz="0 0 -0.15"/>
    </visual>
    <visual>
      <geometry>
        <box size="0.05 0.033 0.05"/>
      </geometry>
      <material name="grey"/>
      <origin rpy="0 0 0" xyz="0 0.033 -0.275"/>
    </visual>
    <collision>
      <geometry>
        <box size="0.08 0.08 0.3"/>
      </geometry>
      <origin rpy="0 0 0" xyz="0 0 -0.15"/>
    </collision>
    <collision>
      <geometry>
        <box size="0.05 0.033 0.05"/>
      </geometry>
      <origin rpy="0 0 0" xyz="0 0.033 -0.275"/>
    </collision>
  </link>
  <link name="r_ankle_pitch_link">
    <inertial>
      <origin rpy="0 0 0" xyz="0.0 -0.0 0.0"/>
      <mass value="1.0"/>
      <inertia ixx="1.000" ixy="0.000" ixz="0.000" iyy="1.000" iyz="0.000" izz="1.000"/>
    </inertial>
  </link>
  <link name="r_astragalus_link">
    <inertial>
      <origin rpy="0 0 0" xyz="3.026e-3 -0.0035 -9.323e-3"/>
      <mass value="3.8994"/>
      <inertia ixx="0.062" ixy="-1.417e-4" ixz="-0.004" iyy="0.059" iyz="0.002" izz="0.011"/>
    </inertial>
    <visual>
      <geometry>
        <box size="0.08 0.08 0.124"/>
      </geometry>
      <material name="grey"/>
      <origin rpy="0 0 0" xyz="0 0 -0.062"/>
    </visual>
    <collision>
      <geometry>
        <box size="0.08 0.08 0.124"/>
      </geometry>
      <origin rpy="0 0 0" xyz="0 0 -0.062"/>
    </collision>
    <visual>
      <geometry>
        <box size="0.2 0.1 0.01"/>
      </geometry>
      <material name="grey"/>
      <origin rpy="0 0 0" xyz="0.05 0 -0.129"/>
    </visual>
    <collision>
      <geometry>
        <box size="0.2 0.1 0.01"/>
      </geometry>
      <origin rpy="0 0 0" xyz="0.05 0 -0.129"/>
    </collision>
    <!-- OJO, falta bajarlo -link5/2-->
  </link>
  <link name="r_sole">
    <inertial>
      <origin rpy="0 0 0" xyz="0.0 -0.0 0.0"/>
      <mass value="0.001"/>
      <inertia ixx="1.000" ixy="0.000" ixz="0.000" iyy="1.000" iyz="0.000" izz="1.000"/>
    </inertial>
  </link>
  <joint name="l_hip_yaw" type="revolute">
    <parent link="waist"/>
    <child link="l_hip_yaw_link"/>
    <origin rpy="0 0 0" xyz="0 0.146 0"/>
    <!--y=Leg_link1-->
    <axis xyz="0 0 1"/>
    <limit effort="30.0" lower="-0.523598775598" upper="0.418879020479" velocity="3.0"/>
    <dynamics damping="0.0" friction="0.0"/>
  </joint>
  <joint name="l_hip_roll" type="revolute">
    <parent link="l_hip_yaw_link"/>
    <child link="l_hip_roll_link"/>
    <origin rpy="0 0 0" xyz="0 0 0"/>
    <axis xyz="1 0 0"/>
    <limit effort="30.0" lower="-0.698131700798" upper="0.523598775598" velocity="3.0"/>
    <dynamics damping="0.0" friction="0.0"/>
  </joint>
  <joint name="l_hip_pitch" type="revolute">
    <parent link="l_hip_roll_link"/>
    <child link="l_femur_link"/>
    <origin rpy="0 0 0" xyz="0 0 0"/>
    <axis xyz="0 1 0"/>
    <limit effort="30.0" lower="-2.09439510239" upper="0.785398163397" velocity="3.0"/>
    <dynamics damping="0.0" friction="0.0"/>
  </joint>
  <joint name="l_knee_pitch" type="revolute">
    <parent link="l_femur_link"/>
    <child link="l_tibia_link"/>
    <origin rpy="0 0 0" xyz="0 0 -0.33"/>
    <axis xyz="0 1 0"/>
    <limit effort="30.0" lower="0.0" upper="1.57079632679" velocity="3.0"/>
    <dynamics damping="0.0" friction="0.0"/>
  </joint>
  <joint name="l_ankle_pitch" type="revolute">
    <parent link="l_tibia_link"/>
    <child link="l_ankle_pitch_link"/>
    <origin rpy="0 0 0" xyz="0 -0.033 -0.3"/>
    <axis xyz="0 1 0"/>
    <limit effort="30.0" lower="-0.349065850399" upper="0.349065850399" velocity="3.0"/>
    <dynamics damping="0.0" friction="0.0"/>
  </joint>
  <joint name="l_ankle_roll" type="revolute">
    <parent link="l_ankle_pitch_link"/>
    <child link="l_astragalus_link"/>
    <origin rpy="0 0 0" xyz="0 0 0"/>
    <axis xyz="1 0 0"/>
    <limit effort="30.0" lower="-1.4835298642" upper="1.4835298642" velocity="3.0"/>
    <dynamics damping="0.0" friction="0.0"/>
  </joint>
  <joint name="l_sole_joint" type="fixed">
    <parent link="l_astragalus_link"/>
    <child link="l_sole"/>
    <origin rpy="0 0 0" xyz="0 0 -0.124"/>
  </joint>
  <transmission name="l_hip_yaw_trans">
    <type>transmission_interface/SimpleTransmission</type>
    <joint name="l_hip_yaw"/>
    <actuator name="l_hip_yaw_motor">
      <hardwareInterface>EffortJointInterface</hardwareInterface>
      <mechanicalReduction>1.0</mechanicalReduction>
    </actuator>
  </transmission>
  <transmission name="l_hip_roll_trans">
    <type>transmission_interface/SimpleTransmission</type>
    <joint name="l_hip_roll"/>
    <actuator name="l_hip_roll_motor">
      <hardwareInterface>EffortJointInterface</hardwareInterface>
      <mechanicalReduction>1.0</mechanicalReduction>
    </actuator>
  </transmission>
  <transmission name="l_hip_pitch_trans">
    <type>transmission_interface/SimpleTransmission</type>
    <joint name="l_hip_pitch"/>
    <actuator name="l_hip_pitch_motor">
      <hardwareInterface>EffortJointInterface</hardwareInterface>
      <mechanicalReduction>1.0</mechanicalReduction>
    </actuator>
  </transmission>
  <transmission name="l_knee_pitch_trans">
    <type>transmission_interface/SimpleTransmission</type>
    <joint name="l_knee_pitch"/>
    <actuator name="l_knee_pitch_motor">
      <hardwareInterface>EffortJointInterface</hardwareInterface>
      <mechanicalReduction>1.0</mechanicalReduction>
    </actuator>
  </transmission>
  <transmission name="l_ankle_pitch_trans">
    <type>transmission_interface/SimpleTransmission</type>
    <joint name="l_ankle_pitch"/>
    <actuator name="l_ankle_pitch_motor">
      <hardwareInterface>EffortJointInterface</hardwareInterface>
      <mechanicalReduction>1.0</mechanicalReduction>
    </actuator>
  </transmission>
  <transmission name="l_ankle_roll_trans">
    <type>transmission_interface/SimpleTransmission</type>
    <joint name="l_ankle_roll"/>
    <actuator name="l_ankle_roll_motor">
      <hardwareInterface>EffortJointInterface</hardwareInterface>
      <mechanicalReduction>1.0</mechanicalReduction>
    </actuator>
  </transmission>
  <joint name="r_hip_yaw" type="revolute">
    <parent link="waist"/>
    <child link="r_hip_yaw_link"/>
    <origin rpy="0 0 0" xyz="0 -0.146 0"/>
    <!--y=Leg_link1-->
    <axis xyz="0 0 1"/>
    <limit effort="30.0" lower="-0.523598775598" upper="0.418879020479" velocity="3.0"/>
    <dynamics damping="0.0" friction="0.0"/>
  </joint>
  <joint name="r_hip_roll" type="revolute">
    <parent link="r_hip_yaw_link"/>
    <child link="r_hip_roll_link"/>
    <origin rpy="0 0 0" xyz="0 0 0"/>
    <axis xyz="1 0 0"/>
    <limit effort="30.0" lower="-0.698131700798" upper="0.523598775598" velocity="3.0"/>
    <dynamics damping="0.0" friction="0.0"/>
  </joint>
  <joint name="r_hip_pitch" type="revolute">
    <parent link="r_hip_roll_link"/>
    <child link="r_femur_link"/>
    <origin rpy="0 0 0" xyz="0 0 0"/>
    <axis xyz="0 1 0"/>
    <limit effort="30.0" lower="-2.09439510239" upper="0.785398163397" velocity="3.0"/>
    <dynamics damping="0.0" friction="0.0"/>
  </joint>
  <joint name="r_knee_pitch" type="revolute">
    <parent link="r_femur_link"/>
    <child link="r_tibia_link"/>
    <origin rpy="0 0 0" xyz="0 0 -0.33"/>
    <axis xyz="0 1 0"/>
    <limit effort="30.0" lower="0.0" upper="1.57079632679" velocity="3.0"/>
    <dynamics damping="0.0" friction="0.0"/>
  </joint>
  <joint name="r_ankle_pitch" type="revolute">
    <parent link="r_tibia_link"/>
    <child link="r_ankle_pitch_link"/>
    <origin rpy="0 0 0" xyz="0 0.033 -0.3"/>
    <axis xyz="0 1 0"/>
    <limit effort="30.0" lower="-0.349065850399" upper="0.349065850399" velocity="3.0"/>
    <dynamics damping="0.0" friction="0.0"/>
  </joint>
  <joint name="r_ankle_roll" type="revolute">
    <parent link="r_ankle_pitch_link"/>
    <child link="r_astragalus_link"/>
    <origin rpy="0 0 0" xyz="0 0 0"/>
    <axis xyz="1 0 0"/>
    <limit effort="30.0" lower="-1.4835298642" upper="1.4835298642" velocity="3.0"/>
    <dynamics damping="0.0" friction="0.0"/>
  </joint>
  <joint name="r_sole_joint" type="fixed">
    <parent link="r_astragalus_link"/>
    <child link="r_sole"/>
    <origin rpy="0 0 0" xyz="0 0 -0.124"/>
  </joint>
  <transmission name="r_hip_yaw_trans">
    <type>transmission_interface/SimpleTransmission</type>
    <joint name="r_hip_yaw"/>
    <actuator name="r_hip_yaw_motor">
      <hardwareInterface>EffortJointInterface</hardwareInterface>
      <mechanicalReduction>1.0</mechanicalReduction>
    </actuator>
  </transmission>
  <transmission name="r_hip_roll_trans">
    <type>transmission_interface/SimpleTransmission</type>
    <joint name="r_hip_roll"/>
    <actuator name="r_hip_roll_motor">
      <hardwareInterface>EffortJointInterface</hardwareInterface>
      <mechanicalReduction>1.0</mechanicalReduction>
    </actuator>
  </transmission>
  <transmission name="r_hip_pitch_trans">
    <type>transmission_interface/SimpleTransmission</type>
    <joint name="r_hip_pitch"/>
    <actuator name="r_hip_pitch_motor">
      <hardwareInterface>EffortJointInterface</hardwareInterface>
      <mechanicalReduction>1.0</mechanicalReduction>
    </actuator>
  </transmission>
  <transmission name="r_knee_pitch_trans">
    <type>transmission_interface/SimpleTransmission</type>
    <joint name="r_knee_pitch"/>
    <actuator name="r_knee_pitch_motor">
      <hardwareInterface>EffortJointInterface</hardwareInterface>
      <mechanicalReduction>1.0</mechanicalReduction>
    </actuator>
  </transmission>
  <transmission name="r_ankle_pitch_trans">
    <type>transmission_interface/SimpleTransmission</type>
    <joint name="r_ankle_pitch"/>
    <actuator name="r_ankle_pitch_motor">
      <hardwareInterface>EffortJointInterface</hardwareInterface>
      <mechanicalReduction>1.0</mechanicalReduction>
    </actuator>
  </transmission>
  <transmission name="r_ankle_roll_trans">
    <type>transmission_interface/SimpleTransmission</type>
    <joint name="r_ankle_roll"/>
    <actuator name="r_ankle_roll_motor">
      <hardwareInterface>EffortJointInterface</hardwareInterface>
      <mechanicalReduction>1.0</mechanicalReduction>
    </actuator>
  </transmission>
  <link name="l_shoulder_pitch_link">
    <inertial>
      <origin rpy="0 0 0" xyz="0.0 0.0 0.0"/>
      <mass value="0.005"/>
      <inertia ixx="1.000" ixy="0.000" ixz="0.000" iyy="1.000" iyz="0.000" izz="1.000"/>
    </inertial>
  </link>
  <link name="l_shoulder_roll_link">
    <inertial>
      <origin rpy="0 0 0" xyz="0.0 0.0 0.0"/>
      <mass value="0.005"/>
      <inertia ixx="1.000" ixy="0.000" ixz="0.000" iyy="1.000" iyz="0.000" izz="1.000"/>
    </inertial>
  </link>
  <link name="l_shoulder_yaw_link">
    <inertial>
      <origin rpy="0 0 0" xyz="0.0 0.0 0.0"/>
      <mass value="1.750625"/>
      <inertia ixx="7.000e-3" ixy="2.148e-5" ixz="3.931e-5" iyy="7.000e-3" iyz="1.558e-5" izz="8.195e-4"/>
    </inertial>
    <visual>
      <geometry>
        <box size="0.08 0.08 0.337"/>
      </geometry>
      <material name="grey"/>
      <origin rpy="0 0 0" xyz="0 0 -0.1685"/>
    </visual>
    <collision>
      <geometry>
        <box size="0.08 0.08 0.337"/>
      </geometry>
      <origin rpy="0 0 0" xyz="0 0 -0.1685"/>
    </collision>
  </link>
  <link name="l_elbow_pitch_link">
    <inertial>
      <origin rpy="0 0 0" xyz="0.0 0.0 0.0"/>
      <mass value="2.396"/>
      <inertia ixx="3.000e-3" ixy="9.570e-4" ixz="6.522e-6" iyy="3.000e-3" iyz="3.778e-5" izz="3.000e-3"/>
    </inertial>
    <visual>
      <geometry>
        <box size="0.06 0.06 0.21"/>
      </geometry>
      <material name="grey"/>
      <origin rpy="0 0 0" xyz="0 0 -0.105"/>
    </visual>
    <collision>
      <geometry>
        <box size="0.06 0.06 0.21"/>
      </geometry>
      <origin rpy="0 0 0" xyz="0 0 -0.105"/>
    </collision>
  </link>
  <link name="l_wrist_yaw_link">
    <inertial>
      <origin rpy="0 0 0" xyz="0.0 0.0 0.0"/>
      <mass value="0.005"/>
      <inertia ixx="1.000" ixy="0.000" ixz="0.000" iyy="1.000" iyz="0.000" izz="1.000"/>
    </inertial>
  </link>
  <link name="l_wrist_pitch_link">
    <inertial>
      <origin rpy="0 0 0" xyz="0.0 0.0 0.0"/>
      <mass value="0.3"/>
      <inertia ixx="3.400e-4" ixy="0.000" ixz="0.000" iyy="3.125e-4" iyz="0.000" izz="1.525e-4"/>
    </inertial>
  </link>
  <link name="r_shoulder_pitch_link">
    <inertial>
      <origin rpy="0 0 0" xyz="0.0 -0.0 0.0"/>
      <mass value="0.005"/>
      <inertia ixx="1.000" ixy="0.000" ixz="0.000" iyy="1.000" iyz="0.000" izz="1.000"/>
    </inertial>
  </link>
  <link name="r_shoulder_roll_link">
    <inertial>
      <origin rpy="0 0 0" xyz="0.0 -0.0 0.0"/>
      <mass value="0.005"/>
      <inertia ixx="1.000" ixy="0.000" ixz="0.000" iyy="1.000" iyz="0.000" izz="1.000"/>
    </inertial>
  </link>
  <link name="r_shoulder_yaw_link">
    <inertial>
      <origin rpy="0 0 0" xyz="0.0 -0.0 0.0"/>
      <mass value="1.750625"/>
      <inertia ixx="7.000e-3" ixy="2.148e-5" ixz="3.931e-5" iyy="7.000e-3" iyz="1.558e-5" izz="8.195e-4"/>
    </inertial>
    <visual>
      <geometry>
        <box size="0.08 0.08 0.337"/>
      </geometry>
      <material name="grey"/>
      <origin rpy="0 0 0" xyz="0 0 -0.1685"/>
    </visual>
    <collision>
      <geometry>
        <box size="0.08 0.08 0.337"/>
      </geometry>
      <origin rpy="0 0 0" xyz="0 0 -0.1685"/>
    </collision>
  </link>
  <link name="r_elbow_pitch_link">
    <inertial>
      <origin rpy="0 0 0" xyz="0.0 -0.0 0.0"/>
      <mass value="2.396"/>
      <inertia ixx="3.000e-3" ixy="9.570e-4" ixz="6.522e-6" iyy="3.000e-3" iyz="3.778e-5" izz="3.000e-3"/>
    </inertial>
    <visual>
      <geometry>
        <box size="0.06 0.06 0.21"/>
      </geometry>
      <material name="grey"/>
      <origin rpy="0 0 0" xyz="0 0 -0.105"/>
    </visual>
    <collision>
      <geometry>
        <box size="0.06 0.06 0.21"/>
      </geometry>
      <origin rpy="0 0 0" xyz="0 0 -0.105"/>
    </collision>
  </link>
  <link name="r_wrist_yaw_link">
    <inertial>
      <origin rpy="0 0 0" xyz="0.0 -0.0 0.0"/>
      <mass value="0.005"/>
      <inertia ixx="1.000" ixy="0.000" ixz="0.000" iyy="1.000" iyz="0.000" izz="1.000"/>
    </inertial>
  </link>
  <link name="r_wrist_pitch_link">
    <inertial>
      <origin rpy="0 0 0" xyz="0.0 -0.0 0.0"/>
      <mass value="0.3"/>
      <inertia ixx="3.400e-4" ixy="0.000" ixz="0.000" iyy="3.125e-4" iyz="0.000" izz="1.525e-4"/>
    </inertial>
  </link>
  <joint name="l_shoulder_pitch" type="revolute">
    <parent link="waist_pitch_link"/>
    <child link="l_shoulder_pitch_link"/>
    <origin rpy="0 0 0" xyz="-0.0 0.34 0.245"/>
    <axis xyz="0 1 0"/>
    <limit effort="30.0" lower="-3.14159265359" upper="3.14159265359" velocity="3.0"/>
  </joint>
  <joint name="l_shoulder_roll" type="revolute">
    <parent link="l_shoulder_pitch_link"/>
    <child link="l_shoulder_roll_link"/>
    <origin rpy="0 0 0" xyz="0 0 0"/>
    <axis xyz="1 0 0"/>
    <limit effort="30.0" lower="-0.785398163397" upper="2.09439510239" velocity="3.0"/>
  </joint>
  <joint name="l_shoulder_yaw" type="revolute">
    <parent link="l_shoulder_roll_link"/>
    <child link="l_shoulder_yaw_link"/>
    <origin rpy="0 0 0" xyz="0 0 0"/>
    <axis xyz="0 0 1"/>
    <limit effort="30.0" lower="-1.0471975512" upper="1.0471975512" velocity="3.0"/>
  </joint>
  <joint name="l_elbow_pitch" type="revolute">
    <parent link="l_shoulder_yaw_link"/>
    <child link="l_elbow_pitch_link"/>
    <origin rpy="0 0 0" xyz="0 0 -0.337"/>
    <axis xyz="0 1 0"/>
    <limit effort="30.0" lower="-1.74532925199" upper="1.74532925199" velocity="3.0"/>
  </joint>
  <joint name="l_wrist_yaw" type="revolute">
    <parent link="l_elbow_pitch_link"/>
    <child link="l_wrist_yaw_link"/>
    <origin rpy="0 0 0" xyz="0 0 -0.21"/>
    <axis xyz="0 0 1"/>
    <limit effort="30.0" lower="-1.83259571459" upper="1.83259571459" velocity="3.0"/>
  </joint>
  <joint name="l_wrist_pitch" type="revolute">
    <parent link="l_wrist_yaw_link"/>
    <child link="l_wrist_pitch_link"/>
    <origin rpy="0 0 0" xyz="0 0 0"/>
    <axis xyz="0 1 0"/>
    <limit effort="30.0" lower="-0.698131700798" upper="0.959931088597" velocity="3.0"/>
  </joint>
  <transmission name="l_shoulder_pitch_trans">
    <type>transmission_interface/SimpleTransmission</type>
    <joint name="l_shoulder_pitch"/>
    <actuator name="l_shoulder_pitch_motor">
      <hardwareInterface>EffortJointInterface</hardwareInterface>
      <mechanicalReduction>1.0</mechanicalReduction>
    </actuator>
  </transmission>
  <transmission name="l_shoulder_roll_trans">
    <type>transmission_interface/SimpleTransmission</type>
    <joint name="l_shoulder_roll"/>
    <actuator name="l_shoulder_roll_motor">
      <hardwareInterface>EffortJointInterface</hardwareInterface>
      <mechanicalReduction>1.0</mechanicalReduction>
    </actuator>
  </transmission>
  <transmission name="l_shoulder_yaw_trans">
    <type>transmission_interface/SimpleTransmission</type>
    <joint name="l_shoulder_yaw"/>
    <actuator name="l_shoulder_yaw_motor">
      <hardwareInterface>EffortJointInterface</hardwareInterface>
      <mechanicalReduction>1.0</mechanicalReduction>
    </actuator>
  </transmission>
  <transmission name="l_elbow_pitch_trans">
    <type>transmission_interface/SimpleTransmission</type>
    <joint name="l_elbow_pitch"/>
    <actuator name="l_elbow_pitch_motor">
      <hardwareInterface>EffortJointInterface</hardwareInterface>
      <mechanicalReduction>1.0</mechanicalReduction>
    </actuator>
  </transmission>
  <transmission name="l_wrist_yaw_trans">
    <type>transmission_interface/SimpleTransmission</type>
    <joint name="l_wrist_yaw"/>
    <actuator name="l_wrist_yaw_motor">
      <hardwareInterface>EffortJointInterface</hardwareInterface>
      <mechanicalReduction>1.0</mechanicalReduction>
    </actuator>
  </transmission>
  <transmission name="l_wrist_pitch_trans">
    <type>transmission_interface/SimpleTransmission</type>
    <joint name="l_wrist_pitch"/>
    <actuator name="l_wrist_pitch_motor">
      <hardwareInterface>EffortJointInterface</hardwareInterface>
      <mechanicalReduction>1.0</mechanicalReduction>
    </actuator>
  </transmission>
  <joint name="r_shoulder_pitch" type="revolute">
    <parent link="waist_pitch_link"/>
    <child link="r_shoulder_pitch_link"/>
    <origin rpy="0 0 0" xyz="-0.0 -0.34 0.245"/>
    <axis xyz="0 1 0"/>
    <limit effort="30.0" lower="-3.14159265359" upper="3.14159265359" velocity="3.0"/>
  </joint>
  <joint name="r_shoulder_roll" type="revolute">
    <parent link="r_shoulder_pitch_link"/>
    <child link="r_shoulder_roll_link"/>
    <origin rpy="0 0 0" xyz="0 0 0"/>
    <axis xyz="1 0 0"/>
    <limit effort="30.0" lower="-0.785398163397" upper="2.09439510239" velocity="3.0"/>
  </joint>
  <joint name="r_shoulder_yaw" type="revolute">
    <parent link="r_shoulder_roll_link"/>
    <child link="r_shoulder_yaw_link"/>
    <origin rpy="0 0 0" xyz="0 0 0"/>
    <axis xyz="0 0 1"/>
    <limit effort="30.0" lower="-1.0471975512" upper="1.0471975512" velocity="3.0"/>
  </joint>
  <joint name="r_elbow_pitch" type="revolute">
    <parent link="r_shoulder_yaw_link"/>
    <child link="r_elbow_pitch_link"/>
    <origin rpy="0 0 0" xyz="0 0 -0.337"/>
    <axis xyz="0 1 0"/>
    <limit effort="30.0" lower="-1.74532925199" upper="1.74532925199" velocity="3.0"/>
  </joint>
  <joint name="r_wrist_yaw" type="revolute">
    <parent link="r_elbow_pitch_link"/>
    <child link="r_wrist_yaw_link"/>
    <origin rpy="0 0 0" xyz="0 0 -0.21"/>
    <axis xyz="0 0 1"/>
    <limit effort="30.0" lower="-1.83259571459" upper="1.83259571459" velocity="3.0"/>
  </joint>
  <joint name="r_wrist_pitch" type="revolute">
    <parent link="r_wrist_yaw_link"/>
    <child link="r_wrist_pitch_link"/>
    <origin rpy="0 0 0" xyz="0 0 0"/>
    <axis xyz="0 1 0"/>
    <limit effort="30.0" lower="-0.698131700798" upper="0.959931088597" velocity="3.0"/>
  </joint>
  <transmission name="r_shoulder_pitch_trans">
    <type>transmission_interface/SimpleTransmission</type>
    <joint name="r_shoulder_pitch"/>
    <actuator name="r_shoulder_pitch_motor">
      <hardwareInterface>EffortJointInterface</hardwareInterface>
      <mechanicalReduction>1.0</mechanicalReduction>
    </actuator>
  </transmission>
  <transmission name="r_shoulder_roll_trans">
    <type>transmission_interface/SimpleTransmission</type>
    <joint name="r_shoulder_roll"/>
    <actuator name="r_shoulder_roll_motor">
      <hardwareInterface>EffortJointInterface</hardwareInterface>
      <mechanicalReduction>1.0</mechanicalReduction>
    </actuator>
  </transmission>
  <transmission name="r_shoulder_yaw_trans">
    <type>transmission_interface/SimpleTransmission</type>
    <joint name="r_shoulder_yaw"/>
    <actuator name="r_shoulder_yaw_motor">
      <hardwareInterface>EffortJointInterface</hardwareInterface>
      <mechanicalReduction>1.0</mechanicalReduction>
    </actuator>
  </transmission>
  <transmission name="r_elbow_pitch_trans">
    <type>transmission_interface/SimpleTransmission</type>
    <joint name="r_elbow_pitch"/>
    <actuator name="r_elbow_pitch_motor">
      <hardwareInterface>EffortJointInterface</hardwareInterface>
      <mechanicalReduction>1.0</mechanicalReduction>
    </actuator>
  </transmission>
  <transmission name="r_wrist_yaw_trans">
    <type>transmission_interface/SimpleTransmission</type>
    <joint name="r_wrist_yaw"/>
    <actuator name="r_wrist_yaw_motor">
      <hardwareInterface>EffortJointInterface</hardwareInterface>
      <mechanicalReduction>1.0</mechanicalReduction>
    </actuator>
  </transmission>
  <transmission name="r_wrist_pitch_trans">
    <type>transmission_interface/SimpleTransmission</type>
    <joint name="r_wrist_pitch"/>
    <actuator name="r_wrist_pitch_motor">
      <hardwareInterface>EffortJointInterface</hardwareInterface>
      <mechanicalReduction>1.0</mechanicalReduction>
    </actuator>
  </transmission>
  <gazebo>
    <plugin filename="libgazebo_ros_control.so" name="gazebo_ros_control">
      <robotNamespace>/teo</robotNamespace>
    </plugin>
  </gazebo>
  <gazebo reference="torso">
    <mu1>0.9</mu1>
    <mu2>0.9</mu2>
    <material>Gazebo/Black</material>
  </gazebo>
  <gazebo reference="l_femur_link">
    <mu1>0.9</mu1>
    <mu2>0.9</mu2>
    <material>Gazebo/Orange</material>
  </gazebo>
  <gazebo reference="r_femur_link">
    <mu1>0.9</mu1>
    <mu2>0.9</mu2>
    <material>Gazebo/Orange</material>
  </gazebo>
  <!-- TEO visualization -->
  <!--xacro:if value="$(arg simple_vis)">
    <xacro:include filename="$(find teo_description)/urdf/simple_visual.xacro" />
  </xacro:if-->
  <!--xacro:unless complete_vis="$(arg complete_vis)">
    <xacro:include filename="$(find teo_description)/urdf/visualization.xacro" />
  </xacro:unless-->
  <!--xacro:include filename="$(find teo_description)/urdf/simple_visual.xacro" /-->
  <material name="LightGrey">
    <color rgba="0.8 0.8 0.8 1.0"/>
  </material>
</robot>

