<?xml version="1.0"?>
<!-- 

  ROS urdf definition of TEO leg using xacro

  RoboticsLab, University Carlos III of Madrid

  Joint names and properties are according to REP-120:
  Coordinate Frames for Humanoids Robots

  http://ros.org/reps/rep-0120.html

-->


<robot name="teo" xmlns:xacro="http://ros.org/wiki/xacro">

<!-- *** TEO LEG PARAMETERS -->
  <xacro:property name="prop_kg_motor_vol_unit" value="6229.073482" /> <!-- Relation Kg - Volume Unit -->
  <xacro:property name="prop_kg_femur_vol_unit" value="330.0519062" /> <!-- Relation Kg - Volume Unit -->
  <xacro:property name="prop_kg_tibia_vol_unit" value="2638.403042" /> <!-- Relation Kg - Volume Unit -->

<!-- Link lengths -->
	<xacro:property name="leg_link0" value="0.10237" /> <!-- Hip -->
	<xacro:property name="leg_link1" value="0.146" /> <!-- Hip -->
	<xacro:property name="leg_link2" value="0.33" /> <!-- Femur -->
	<xacro:property name="leg_link3" value="0.3" /> <!-- Tibia -->
	<xacro:property name="leg_link4" value="0.033" /> <!-- Patella -->
	<xacro:property name="leg_link5" value="0.124" /> <!-- Astragalus -->


<!-- Minimum angles -->
	<xacro:property name="hip_yaw_lower" value="${-30 * deg_to_rad}" />
	<xacro:property name="hip_roll_lower" value="${-40 * deg_to_rad}" />
	<xacro:property name="hip_pitch_lower" value="${-120 * deg_to_rad}" />
	<xacro:property name="knee_pitch_lower" value="${0 * deg_to_rad}" />
	<xacro:property name="ankle_pitch_lower" value="${-20 * deg_to_rad}" />
	<xacro:property name="ankle_roll_lower" value="${-85 * deg_to_rad}" />

<!-- Maximum angles -->
	<xacro:property name="hip_yaw_upper" value="${24 * deg_to_rad}" />
	<xacro:property name="hip_roll_upper" value="${30 * deg_to_rad}" />
	<xacro:property name="hip_pitch_upper" value="${45 * deg_to_rad}" />
	<xacro:property name="knee_pitch_upper" value="${90 * deg_to_rad}" />
	<xacro:property name="ankle_pitch_upper" value="${20 * deg_to_rad}" />
	<xacro:property name="ankle_roll_upper" value="${85 * deg_to_rad}" />

<!-- Effort limit of the angles -->
	<xacro:property name="hip_yaw_effort" value="45.0" />
	<xacro:property name="hip_roll_effort" value="65.0" />
	<xacro:property name="hip_pitch_effort" value="60.0" />
	<xacro:property name="knee_pitch_effort" value="140.0" />
	<xacro:property name="ankle_pitch_effort" value="85.0" />
	<xacro:property name="ankle_roll_effort" value="65.0" />

<!-- Velocity limit of the angles-->
	<xacro:property name="hip_yaw_velocity" value="4.0" />
	<xacro:property name="hip_roll_velocity" value="4.0" />
	<xacro:property name="hip_pitch_velocity" value="4.0" />
	<xacro:property name="knee_pitch_velocity" value="4.0" />
	<xacro:property name="ankle_pitch_velocity" value="4.0" />
	<xacro:property name="ankle_roll_velocity" value="4.0" />

<!-- Damping of the joints-->
	<xacro:property name="hip_yaw_damping" value="1.0" />
	<xacro:property name="hip_roll_damping" value="1.0" />
	<xacro:property name="hip_pitch_damping" value="1.0" />
	<xacro:property name="knee_pitch_damping" value="1.0" />
	<xacro:property name="ankle_pitch_damping" value="1.0" />
	<xacro:property name="ankle_roll_damping" value="1.0" />

<!-- Friction of the joints--> <!-- IT'S NOT USED IN GAZEBO-->
	<xacro:property name="hip_yaw_friction" value="1.0" />
	<xacro:property name="hip_roll_friction" value="1.0" />
	<xacro:property name="hip_pitch_friction" value="1.0" />
	<xacro:property name="knee_pitch_friction" value="1.0" />
	<xacro:property name="ankle_pitch_friction" value="1.0" />
	<xacro:property name="ankle_roll_friction" value="1.0" />

<!-- Joint reductions-->
	<xacro:property name="hip_yaw_reduction" value="1.0" />
	<xacro:property name="hip_roll_reduction" value="1.0" />
	<xacro:property name="hip_pitch_reduction" value="1.0" />
	<xacro:property name="knee_pitch_reduction" value="1.0" />
	<xacro:property name="ankle_pitch_reduction" value="1.0" />
	<xacro:property name="ankle_roll_reduction" value="1.0" />


<!-- *** TEO LEG MACROS -->

  <!-- Links -->
  <xacro:macro name="legs_links" params="side reflect">
    <link name="${side}_hip_yaw_link">
      <inertial>
        <origin xyz="0.000949 ${-reflect*0.0} 0.055583" rpy="0 0 0"/>
        <!-- <mass value="0.001"/> -->
        <mass value="1"/>
        <inertia ixx="3.4076E-7" ixy="${-reflect*0.0}" ixz="5.4E-10" iyy="5.7638E-7" iyz="${-reflect*3.7186E-7}" izz="0.00084231334"/>
      </inertial>
			<xacro:insert_visualization_hip_yaw side="${side}" reflect="{reflect}"/>
    </link>
    <link name="${side}_hip_roll_link">
      <inertial>
        <origin xyz="0.006983 ${-reflect*0.001958} 0.000002" rpy="0 0 0"/>
        <!-- <mass value="0.001"/> -->
        <mass value="1"/>
        <inertia ixx="3.6847E-7" ixy="${-reflect*4.34E-9}" ixz="1.0E-11" iyy="1.9052E-7" iyz="${-reflect*0.0}" izz="4.5536E-7"/>
      </inertial>
			<xacro:insert_visualization_hip_pitch side="${side}" reflect="{reflect}"/>
    </link>
    <link name="${side}_femur_link">
      <inertial>
        <origin xyz="${-0.013877} ${-reflect*0.0} ${-0.172570}" rpy="0 0 0"/>
        <!-- <mass value="1.844"/> -->
        <mass value="1"/>
        <inertia ixx="4.453648E-5" ixy="${-reflect*-1.0E-11}" ixz="0.00000130498" iyy="4.46349E-5" iyz="${-reflect*3.0E-11}" izz="2.207083E-5"/>
      </inertial>
      <xacro:insert_visualization_femur_link side="${side}" reflect="${reflect}"/>
    </link>
    <link name="${side}_tibia_link">
      <inertial>
        <!-- <origin xyz="${-0.013-0.001019} ${-reflect*(-(leg_link4)+0.024670)} ${-leg_link3+0.127850}" rpy="0 0 0"/> -->
        <origin xyz="${-0.010351} ${-reflect*0.0} -0.142721" rpy="0 0 0"/>
        <!-- <mass value="2.0817"/> -->
        <mass value="1"/>
        <inertia ixx="4.644211E-5" ixy="${-reflect*0.0}" ixz="-7.32E-9" iyy="4.548272E-5" iyz="${-reflect*-2.0E-11}" izz="8.16616E-6"/>
      </inertial>
      <xacro:insert_visualization_tibia_link side="${side}" reflect="${reflect}"/>
    </link>
    <link name="${side}_ankle_pitch_link">
      <inertial>
        <origin xyz="-0.007339 ${-reflect*-0.012149} 0.000003" rpy="0 0 0"/>
        <mass value="1.0"/>
        <inertia ixx="3.3782E-7" ixy="${-reflect*-1.65E-9}" ixz="0.0" iyy="3.8475E-7" iyz="${-reflect*0.0}" izz="5.8551E-7"/>
      </inertial>
      <xacro:insert_visualization_ankle_pitch side="${side}" reflect="${reflect}"/>
    </link>
    <link name="${side}_astragalus_link">
      <inertial>
        <origin xyz="-0.006788 ${-reflect*0.000020} -0.042127" rpy="0 0 0"/>
        <mass value="1"/>
        <inertia ixx="2.6324E-7" ixy="${-reflect*0.0}" ixz="7.4E-9" iyy="0.000000571" iyz="${-reflect*0}" izz="4.633E-7"/>
      </inertial>
      <xacro:insert_visualization_ankle_roll side="${side}" reflect="${reflect}"/>
    </link>
    <link name="${side}_sole">
      <inertial>
        <origin xyz="0.022629 ${-reflect*0.002448} 0.011325" rpy="0 0 0"/>
        <mass value="1"/>
        <inertia ixx="6.699E-7" ixy="${-reflect*-0.000000093}" ixz="9.066E-8" iyy="1.69929E-6" iyz="${-reflect*7.08E-9}" izz="2.28359E-6"/>
      </inertial>
      <xacro:insert_visualization_foot side="${side}" reflect="${reflect}"/>
      <xacro:insert_visualization_union_sensorFT_foot side="${side}" reflect="${reflect}"/>
    </link>

  </xacro:macro>


  <!-- Joints -->
  <xacro:macro name="legs_joints" params="side reflect effortTransmission velocityTransmission positionTransmission">
    <joint name="${side}_hip_yaw" type="revolute">
      <parent link="waist"/>
      <child link="${side}_hip_yaw_link"/>
      <origin xyz="0 ${reflect*leg_link1} ${-leg_link0}" rpy="0 0 0"/> <!--y=Leg_link1-->
      <axis xyz="0 0 1"/>
      <limit velocity="${hip_yaw_velocity}" effort="${hip_yaw_effort}" lower="${hip_yaw_lower}" upper="${hip_yaw_upper}"/>
			<dynamics damping="${hip_yaw_damping}" friction="${hip_yaw_friction}"/>
    </joint> 

    <joint name="${side}_hip_roll" type="revolute">
      <parent link="${side}_hip_yaw_link"/>
      <child link="${side}_hip_roll_link"/>
      <origin xyz="0 0 0" rpy="0 0 0"/>
      <axis xyz="1 0 0"/>
      <limit velocity="${hip_roll_velocity}" effort="${hip_roll_effort}" lower="${hip_roll_lower}" upper="${hip_roll_upper}"/>
			<dynamics damping="${hip_roll_damping}" friction="${hip_roll_friction}"/>
    </joint> 

    <joint name="${side}_hip_pitch" type="revolute">
      <parent link="${side}_hip_roll_link"/>
      <child link="${side}_femur_link"/>
      <origin xyz="0 0 0" rpy="0 0 0"/>
      <axis xyz="0 1 0"/>
      <limit velocity="${hip_pitch_velocity}" effort="${hip_pitch_effort}" lower="${hip_pitch_lower}" upper="${hip_pitch_upper}"/>
			<dynamics damping="${hip_pitch_damping}" friction="${hip_pitch_friction}"/>
    </joint> 

    <joint name="${side}_knee_pitch" type="revolute">
      <parent link="${side}_femur_link"/>
      <child link="${side}_tibia_link"/>
      <origin xyz="0 0 -${leg_link2}" rpy="0 0 0"/>
      <axis xyz="0 1 0"/>
      <limit velocity="${knee_pitch_velocity}" effort="${knee_pitch_effort}" lower="${knee_pitch_lower}" upper="${knee_pitch_upper}"/>
			<dynamics damping="${knee_pitch_damping}" friction="${knee_pitch_friction}"/>
    </joint> 

    <joint name="${side}_ankle_pitch" type="revolute">
      <parent link="${side}_tibia_link"/>
      <child link="${side}_ankle_pitch_link"/>
      <origin xyz="0 ${reflect*-leg_link4} -${leg_link3}" rpy="0 0 0"/>
      <axis xyz="0 1 0"/>
      <limit velocity="${ankle_pitch_velocity}" effort="${ankle_pitch_effort}" lower="${ankle_pitch_lower}" upper="${ankle_pitch_upper}"/>
			<dynamics damping="${ankle_pitch_damping}" friction="${ankle_pitch_friction}"/>
    </joint> 

    <joint name="${side}_ankle_roll" type="revolute">
      <parent link="${side}_ankle_pitch_link"/>
      <child link="${side}_astragalus_link"/>
      <origin xyz="0 0 0" rpy="0 0 0"/>
      <axis xyz="1 0 0"/>
      <limit velocity="${ankle_roll_velocity}" effort="${ankle_roll_effort}" lower="${ankle_roll_lower}" upper="${ankle_roll_upper}"/>
			<dynamics damping="${ankle_roll_damping}" friction="${ankle_roll_friction}"/>
    </joint> 

    <joint name="${side}_sole_joint" type="fixed">
      <parent link="${side}_astragalus_link"/>
      <child link="${side}_sole"/>
      <origin xyz="0 0 -${leg_link5}" rpy="0 0 0"/>
    </joint> 

    <xacro:limb_joint_simple_transmission name="hip" side="${side}" axis="yaw" reduction="${hip_yaw_reduction}" effortTransmission="${effortTransmission}" velocityTransmission="${velocityTransmission}" positionTransmission="${positionTransmission}"/>
    <xacro:limb_joint_simple_transmission name="hip" side="${side}" axis="roll" reduction="${hip_roll_reduction}" effortTransmission="${effortTransmission}" velocityTransmission="${velocityTransmission}" positionTransmission="${positionTransmission}"/>
    <xacro:limb_joint_simple_transmission name="hip" side="${side}" axis="pitch" reduction="${hip_pitch_reduction}" effortTransmission="${effortTransmission}" velocityTransmission="${velocityTransmission}" positionTransmission="${positionTransmission}"/>
    <xacro:limb_joint_simple_transmission name="knee" side="${side}" axis="pitch" reduction="${knee_pitch_reduction}" effortTransmission="${effortTransmission}" velocityTransmission="${velocityTransmission}" positionTransmission="${positionTransmission}"/>
    <xacro:limb_joint_simple_transmission name="ankle" side="${side}" axis="pitch" reduction="${ankle_pitch_reduction}" effortTransmission="${effortTransmission}" velocityTransmission="${velocityTransmission}" positionTransmission="${positionTransmission}"/>
    <xacro:limb_joint_simple_transmission name="ankle" side="${side}" axis="roll" reduction="${ankle_roll_reduction}" effortTransmission="${effortTransmission}" velocityTransmission="${velocityTransmission}" positionTransmission="${positionTransmission}"/>

  </xacro:macro>

  <xacro:legs_links side="l" reflect="1"/>
  <xacro:legs_links side="r" reflect="-1"/>  
  <xacro:legs_joints side="l" reflect="1" effortTransmission="1" velocityTransmission="0" positionTransmission="0"/>
  <xacro:legs_joints side="r" reflect="-1" effortTransmission="1" velocityTransmission="0" positionTransmission="0"/> 

</robot>
